[36m[2021-04-11 14:58:31 DEBUG] [cli:73][39m ###############################################################################
[36m[2021-04-11 14:58:31 DEBUG] [cli:74][39m Running command 'run'
[36m[2021-04-11 14:58:31 DEBUG] [cli:78][39m Using settings file '/home/luisreciomelero/.chaostoolkit/settings.yaml'
[36m[2021-04-11 14:58:32 DEBUG] [settings:26][39m The Chaos Toolkit settings file could not be found at '/home/luisreciomelero/.chaostoolkit/settings.yaml'.
[36m[2021-04-11 14:58:32 DEBUG] [__init__:355][39m No controls to apply on 'loader'
[36m[2021-04-11 14:58:32 DEBUG] [__init__:355][39m No controls to apply on 'loader'
[36m[2021-04-11 14:58:32 DEBUG] [caching:25][39m Building activity cache...
[36m[2021-04-11 14:58:32 DEBUG] [caching:35][39m Cached 2 activities
[32m[2021-04-11 14:58:32 INFO] [experiment:47][39m Validating the experiment's syntax
[36m[2021-04-11 14:58:32 DEBUG] [configuration:54][39m Loading configuration...
[36m[2021-04-11 14:58:32 DEBUG] [secret:75][39m Loading secrets...
[36m[2021-04-11 14:58:32 DEBUG] [secret:92][39m Secrets loaded
[36m[2021-04-11 14:58:33 DEBUG] [caching:42][39m Clearing activities cache
[31m[2021-04-11 14:58:33 ERROR] [cli:174][39m hypothesis probe must have a tolerance entry
[36m[2021-04-11 14:58:33 DEBUG] [cli:175][39m hypothesis probe must have a tolerance entry
[36m[2021-04-11 14:59:46 DEBUG] [cli:73][39m ###############################################################################
[36m[2021-04-11 14:59:46 DEBUG] [cli:74][39m Running command 'run'
[36m[2021-04-11 14:59:46 DEBUG] [cli:78][39m Using settings file '/home/luisreciomelero/.chaostoolkit/settings.yaml'
[36m[2021-04-11 14:59:47 DEBUG] [settings:26][39m The Chaos Toolkit settings file could not be found at '/home/luisreciomelero/.chaostoolkit/settings.yaml'.
[36m[2021-04-11 14:59:47 DEBUG] [__init__:355][39m No controls to apply on 'loader'
[36m[2021-04-11 14:59:47 DEBUG] [__init__:355][39m No controls to apply on 'loader'
[36m[2021-04-11 14:59:47 DEBUG] [caching:25][39m Building activity cache...
[36m[2021-04-11 14:59:47 DEBUG] [caching:35][39m Cached 2 activities
[32m[2021-04-11 14:59:47 INFO] [experiment:47][39m Validating the experiment's syntax
[36m[2021-04-11 14:59:47 DEBUG] [configuration:54][39m Loading configuration...
[36m[2021-04-11 14:59:47 DEBUG] [secret:75][39m Loading secrets...
[36m[2021-04-11 14:59:47 DEBUG] [secret:92][39m Secrets loaded
[32m[2021-04-11 14:59:48 INFO] [experiment:96][39m Experiment looks valid
[36m[2021-04-11 14:59:48 DEBUG] [caching:42][39m Clearing activities cache
[36m[2021-04-11 14:59:48 DEBUG] [caching:25][39m Building activity cache...
[36m[2021-04-11 14:59:48 DEBUG] [caching:35][39m Cached 2 activities
[36m[2021-04-11 14:59:48 DEBUG] [configuration:54][39m Loading configuration...
[36m[2021-04-11 14:59:48 DEBUG] [secret:75][39m Loading secrets...
[36m[2021-04-11 14:59:48 DEBUG] [secret:92][39m Secrets loaded
[32m[2021-04-11 14:59:48 INFO] [run:323][39m Running experiment: Â¿QuÃ© ocurre cuando eliminamos el deployment que gestiona el microservicio create?
[36m[2021-04-11 14:59:48 DEBUG] [__init__:39][39m Initializing controls
[32m[2021-04-11 14:59:48 INFO] [run:342][39m Steady-state strategy: default
[32m[2021-04-11 14:59:48 INFO] [run:345][39m Rollbacks strategy: default
[36m[2021-04-11 14:59:48 DEBUG] [__init__:355][39m No controls to apply on 'experiment'
[36m[2021-04-11 14:59:48 DEBUG] [run:466][39m Running steady-state hypothesis before the method
[32m[2021-04-11 14:59:48 INFO] [hypothesis:183][39m Steady state hypothesis: Deployment available
[36m[2021-04-11 14:59:48 DEBUG] [__init__:355][39m No controls to apply on 'hypothesis'
[36m[2021-04-11 14:59:48 DEBUG] [__init__:355][39m No controls to apply on 'activity'
[32m[2021-04-11 14:59:48 INFO] [activity:161][39m Probe: deployment-fully-available
[36m[2021-04-11 14:59:48 DEBUG] [python:34][39m Activity 'deployment-fully-available' loaded from '/home/luisreciomelero/.local/lib/python3.8/site-packages/chaosk8s/deployment/probes.py'
[36m[2021-04-11 14:59:48 DEBUG] [__init__:65][39m Using Kubernetes context: default
[36m[2021-04-11 14:59:48 DEBUG] [probes:92][39m Watching events for 30s
[36m[2021-04-11 15:00:12 DEBUG] [__init__:355][39m No controls to apply on 'activity'
[36m[2021-04-11 15:00:12 DEBUG] [__init__:355][39m No controls to apply on 'hypothesis'
[33m[2021-04-11 15:00:12 WARNING] [run:390][39m Received a termination signal (Ctrl-C)...
[32m[2021-04-11 15:00:12 INFO] [run:421][39m Experiment ended with status: interrupted
[36m[2021-04-11 15:00:12 DEBUG] [__init__:355][39m No controls to apply on 'experiment'
[36m[2021-04-11 15:00:12 DEBUG] [__init__:72][39m Cleaning up controls
[36m[2021-04-11 15:00:12 DEBUG] [caching:42][39m Clearing activities cache
[36m[2021-04-11 15:00:57 DEBUG] [cli:73][39m ###############################################################################
[36m[2021-04-11 15:00:57 DEBUG] [cli:74][39m Running command 'run'
[36m[2021-04-11 15:00:57 DEBUG] [cli:78][39m Using settings file '/home/luisreciomelero/.chaostoolkit/settings.yaml'
[36m[2021-04-11 15:00:57 DEBUG] [settings:26][39m The Chaos Toolkit settings file could not be found at '/home/luisreciomelero/.chaostoolkit/settings.yaml'.
[36m[2021-04-11 15:00:57 DEBUG] [__init__:355][39m No controls to apply on 'loader'
[36m[2021-04-11 15:00:57 DEBUG] [__init__:355][39m No controls to apply on 'loader'
[36m[2021-04-11 15:00:57 DEBUG] [caching:25][39m Building activity cache...
[36m[2021-04-11 15:00:57 DEBUG] [caching:35][39m Cached 2 activities
[32m[2021-04-11 15:00:57 INFO] [experiment:47][39m Validating the experiment's syntax
[36m[2021-04-11 15:00:57 DEBUG] [configuration:54][39m Loading configuration...
[36m[2021-04-11 15:00:57 DEBUG] [secret:75][39m Loading secrets...
[36m[2021-04-11 15:00:57 DEBUG] [secret:92][39m Secrets loaded
[32m[2021-04-11 15:00:58 INFO] [experiment:96][39m Experiment looks valid
[36m[2021-04-11 15:00:58 DEBUG] [caching:42][39m Clearing activities cache
[36m[2021-04-11 15:00:58 DEBUG] [caching:25][39m Building activity cache...
[36m[2021-04-11 15:00:58 DEBUG] [caching:35][39m Cached 2 activities
[36m[2021-04-11 15:00:58 DEBUG] [configuration:54][39m Loading configuration...
[36m[2021-04-11 15:00:58 DEBUG] [secret:75][39m Loading secrets...
[36m[2021-04-11 15:00:58 DEBUG] [secret:92][39m Secrets loaded
[32m[2021-04-11 15:00:58 INFO] [run:323][39m Running experiment: Â¿QuÃ© ocurre cuando eliminamos el deployment que gestiona el microservicio create?
[36m[2021-04-11 15:00:58 DEBUG] [__init__:39][39m Initializing controls
[32m[2021-04-11 15:00:58 INFO] [run:342][39m Steady-state strategy: default
[32m[2021-04-11 15:00:58 INFO] [run:345][39m Rollbacks strategy: always
[36m[2021-04-11 15:00:58 DEBUG] [__init__:355][39m No controls to apply on 'experiment'
[36m[2021-04-11 15:00:58 DEBUG] [run:466][39m Running steady-state hypothesis before the method
[32m[2021-04-11 15:00:58 INFO] [hypothesis:183][39m Steady state hypothesis: Deployment available
[36m[2021-04-11 15:00:58 DEBUG] [__init__:355][39m No controls to apply on 'hypothesis'
[36m[2021-04-11 15:00:58 DEBUG] [__init__:355][39m No controls to apply on 'activity'
[32m[2021-04-11 15:00:58 INFO] [activity:161][39m Probe: deployment-fully-available
[36m[2021-04-11 15:00:58 DEBUG] [python:34][39m Activity 'deployment-fully-available' loaded from '/home/luisreciomelero/.local/lib/python3.8/site-packages/chaosk8s/deployment/probes.py'
[36m[2021-04-11 15:00:58 DEBUG] [__init__:65][39m Using Kubernetes context: default
[36m[2021-04-11 15:00:58 DEBUG] [probes:92][39m Watching events for 30s
[36m[2021-04-11 15:01:28 DEBUG] [probes:114][39m Timed out!
[36m[2021-04-11 15:01:28 DEBUG] [activity:235][39m Activity failed
    Traceback (most recent call last):
      File "/home/luisreciomelero/.local/lib/python3.8/site-packages/chaoslib/provider/python.py", line 55, in run_python_activity
        return func(**arguments)
      File "/home/luisreciomelero/.local/lib/python3.8/site-packages/chaosk8s/deployment/probes.py", line 165, in deployment_fully_available
        raise ActivityFailed(
    chaoslib.exceptions.ActivityFailed: deployment '' failed to recover within 30s
    
    During handling of the above exception, another exception occurred:
    
    Traceback (most recent call last):
      File "/home/luisreciomelero/.local/lib/python3.8/site-packages/chaoslib/activity.py", line 228, in run_activity
        result = run_python_activity(activity, configuration, secrets)
      File "/home/luisreciomelero/.local/lib/python3.8/site-packages/chaoslib/provider/python.py", line 57, in run_python_activity
        raise ActivityFailed(
      File "/home/luisreciomelero/.local/lib/python3.8/site-packages/chaoslib/provider/python.py", line 55, in run_python_activity
        return func(**arguments)
      File "/home/luisreciomelero/.local/lib/python3.8/site-packages/chaosk8s/deployment/probes.py", line 165, in deployment_fully_available
        raise ActivityFailed(
    chaoslib.exceptions.ActivityFailed: chaoslib.exceptions.ActivityFailed: deployment '' failed to recover within 30s
[31m[2021-04-11 15:01:28 ERROR] [activity:188][39m   => failed: chaoslib.exceptions.ActivityFailed: deployment '' failed to recover within 30s
[36m[2021-04-11 15:01:28 DEBUG] [__init__:355][39m No controls to apply on 'activity'
[33m[2021-04-11 15:01:28 WARNING] [hypothesis:200][39m Probe terminated unexpectedly, so its tolerance could not be validated
[36m[2021-04-11 15:01:28 DEBUG] [__init__:355][39m No controls to apply on 'hypothesis'
[31m[2021-04-11 15:01:28 CRITICAL] [run:477][39m Steady state probe 'deployment-fully-available' is not in the given tolerance so failing this experiment
[33m[2021-04-11 15:01:28 WARNING] [run:580][39m Rollbacks were explicitly requested to be played
[32m[2021-04-11 15:01:28 INFO] [run:809][39m Let's rollback...
[36m[2021-04-11 15:01:28 DEBUG] [__init__:355][39m No controls to apply on 'rollback'
[32m[2021-04-11 15:01:28 INFO] [rollback:28][39m Rollback: create-deployment
[36m[2021-04-11 15:01:28 DEBUG] [__init__:355][39m No controls to apply on 'activity'
[32m[2021-04-11 15:01:28 INFO] [activity:161][39m Action: create-deployment
[36m[2021-04-11 15:01:28 DEBUG] [python:34][39m Activity 'create-deployment' loaded from '/home/luisreciomelero/.local/lib/python3.8/site-packages/chaosk8s/deployment/actions.py'
[36m[2021-04-11 15:01:28 DEBUG] [__init__:65][39m Using Kubernetes context: default
[36m[2021-04-11 15:01:28 DEBUG] [activity:235][39m Activity failed
    Traceback (most recent call last):
      File "/home/luisreciomelero/.local/lib/python3.8/site-packages/chaoslib/provider/python.py", line 55, in run_python_activity
        return func(**arguments)
      File "/home/luisreciomelero/.local/lib/python3.8/site-packages/chaosk8s/deployment/actions.py", line 24, in create_deployment
        with open(spec_path) as f:
    FileNotFoundError: [Errno 2] No such file or directory: 'ms-create-depl'
    
    During handling of the above exception, another exception occurred:
    
    Traceback (most recent call last):
      File "/home/luisreciomelero/.local/lib/python3.8/site-packages/chaoslib/activity.py", line 228, in run_activity
        result = run_python_activity(activity, configuration, secrets)
      File "/home/luisreciomelero/.local/lib/python3.8/site-packages/chaoslib/provider/python.py", line 57, in run_python_activity
        raise ActivityFailed(
      File "/home/luisreciomelero/.local/lib/python3.8/site-packages/chaoslib/provider/python.py", line 55, in run_python_activity
        return func(**arguments)
      File "/home/luisreciomelero/.local/lib/python3.8/site-packages/chaosk8s/deployment/actions.py", line 24, in create_deployment
        with open(spec_path) as f:
    chaoslib.exceptions.ActivityFailed: FileNotFoundError: [Errno 2] No such file or directory: 'ms-create-depl'
[31m[2021-04-11 15:01:28 ERROR] [activity:188][39m   => failed: FileNotFoundError: [Errno 2] No such file or directory: 'ms-create-depl'
[36m[2021-04-11 15:01:28 DEBUG] [__init__:355][39m No controls to apply on 'activity'
[36m[2021-04-11 15:01:28 DEBUG] [__init__:355][39m No controls to apply on 'rollback'
[32m[2021-04-11 15:01:28 INFO] [run:421][39m Experiment ended with status: failed
[36m[2021-04-11 15:01:28 DEBUG] [__init__:355][39m No controls to apply on 'experiment'
[36m[2021-04-11 15:01:28 DEBUG] [__init__:72][39m Cleaning up controls
[36m[2021-04-11 15:01:28 DEBUG] [caching:42][39m Clearing activities cache
[36m[2021-04-11 15:03:30 DEBUG] [cli:73][39m ###############################################################################
[36m[2021-04-11 15:03:30 DEBUG] [cli:74][39m Running command 'run'
[36m[2021-04-11 15:03:30 DEBUG] [cli:78][39m Using settings file '/home/luisreciomelero/.chaostoolkit/settings.yaml'
[36m[2021-04-11 15:03:31 DEBUG] [settings:26][39m The Chaos Toolkit settings file could not be found at '/home/luisreciomelero/.chaostoolkit/settings.yaml'.
[36m[2021-04-11 15:03:31 DEBUG] [__init__:355][39m No controls to apply on 'loader'
[36m[2021-04-11 15:03:31 DEBUG] [__init__:355][39m No controls to apply on 'loader'
[36m[2021-04-11 15:03:31 DEBUG] [caching:25][39m Building activity cache...
[36m[2021-04-11 15:03:31 DEBUG] [caching:35][39m Cached 2 activities
[32m[2021-04-11 15:03:31 INFO] [experiment:47][39m Validating the experiment's syntax
[36m[2021-04-11 15:03:31 DEBUG] [configuration:54][39m Loading configuration...
[36m[2021-04-11 15:03:31 DEBUG] [secret:75][39m Loading secrets...
[36m[2021-04-11 15:03:31 DEBUG] [secret:92][39m Secrets loaded
[32m[2021-04-11 15:03:31 INFO] [experiment:96][39m Experiment looks valid
[36m[2021-04-11 15:03:31 DEBUG] [caching:42][39m Clearing activities cache
[36m[2021-04-11 15:03:31 DEBUG] [caching:25][39m Building activity cache...
[36m[2021-04-11 15:03:31 DEBUG] [caching:35][39m Cached 2 activities
[36m[2021-04-11 15:03:31 DEBUG] [configuration:54][39m Loading configuration...
[36m[2021-04-11 15:03:31 DEBUG] [secret:75][39m Loading secrets...
[36m[2021-04-11 15:03:31 DEBUG] [secret:92][39m Secrets loaded
[32m[2021-04-11 15:03:31 INFO] [run:323][39m Running experiment: Â¿QuÃ© ocurre cuando eliminamos el deployment que gestiona el microservicio create?
[36m[2021-04-11 15:03:31 DEBUG] [__init__:39][39m Initializing controls
[32m[2021-04-11 15:03:31 INFO] [run:342][39m Steady-state strategy: default
[32m[2021-04-11 15:03:31 INFO] [run:345][39m Rollbacks strategy: always
[36m[2021-04-11 15:03:31 DEBUG] [__init__:355][39m No controls to apply on 'experiment'
[36m[2021-04-11 15:03:31 DEBUG] [run:466][39m Running steady-state hypothesis before the method
[32m[2021-04-11 15:03:31 INFO] [hypothesis:183][39m Steady state hypothesis: Deployment available
[36m[2021-04-11 15:03:31 DEBUG] [__init__:355][39m No controls to apply on 'hypothesis'
[36m[2021-04-11 15:03:31 DEBUG] [__init__:355][39m No controls to apply on 'activity'
[32m[2021-04-11 15:03:31 INFO] [activity:161][39m Probe: deployment-fully-available
[36m[2021-04-11 15:03:31 DEBUG] [python:34][39m Activity 'deployment-fully-available' loaded from '/home/luisreciomelero/.local/lib/python3.8/site-packages/chaosk8s/deployment/probes.py'
[36m[2021-04-11 15:03:31 DEBUG] [__init__:65][39m Using Kubernetes context: default
[36m[2021-04-11 15:03:31 DEBUG] [probes:92][39m Watching events for 30s
[36m[2021-04-11 15:03:31 DEBUG] [probes:98][39m Deployment 'ms-create-depl' ADDED: Ready Replicas 1 - Unavailable Replicas None - Desired Replicas 1
[36m[2021-04-11 15:03:31 DEBUG] [activity:180][39m   => succeeded with 'True'
[36m[2021-04-11 15:03:31 DEBUG] [__init__:355][39m No controls to apply on 'activity'
[36m[2021-04-11 15:03:31 DEBUG] [hypothesis:211][39m allowed tolerance is True
[32m[2021-04-11 15:03:31 INFO] [hypothesis:221][39m Steady state hypothesis is met!
[36m[2021-04-11 15:03:31 DEBUG] [__init__:355][39m No controls to apply on 'hypothesis'
[32m[2021-04-11 15:03:31 INFO] [run:553][39m Playing your experiment's method now...
[36m[2021-04-11 15:03:31 DEBUG] [__init__:355][39m No controls to apply on 'method'
[36m[2021-04-11 15:03:31 DEBUG] [__init__:355][39m No controls to apply on 'activity'
[32m[2021-04-11 15:03:31 INFO] [activity:161][39m Action: delete-deployment
[36m[2021-04-11 15:03:31 DEBUG] [python:34][39m Activity 'delete-deployment' loaded from '/home/luisreciomelero/.local/lib/python3.8/site-packages/chaosk8s/deployment/actions.py'
[36m[2021-04-11 15:03:31 DEBUG] [__init__:65][39m Using Kubernetes context: default
[36m[2021-04-11 15:03:31 DEBUG] [actions:58][39m Found 0 deployments named 'ms-create-depl'
[36m[2021-04-11 15:03:31 DEBUG] [activity:182][39m   => succeeded without any result value
[32m[2021-04-11 15:03:31 INFO] [activity:198][39m Pausing after activity for 20s...
[36m[2021-04-11 15:03:51 DEBUG] [__init__:355][39m No controls to apply on 'activity'
[36m[2021-04-11 15:03:51 DEBUG] [__init__:355][39m No controls to apply on 'method'
[36m[2021-04-11 15:03:51 DEBUG] [run:496][39m Running steady-state hypothesis after the method
[32m[2021-04-11 15:03:51 INFO] [hypothesis:183][39m Steady state hypothesis: Deployment available
[36m[2021-04-11 15:03:51 DEBUG] [__init__:355][39m No controls to apply on 'hypothesis'
[36m[2021-04-11 15:03:51 DEBUG] [__init__:355][39m No controls to apply on 'activity'
[32m[2021-04-11 15:03:51 INFO] [activity:161][39m Probe: deployment-fully-available
[36m[2021-04-11 15:03:51 DEBUG] [python:34][39m Activity 'deployment-fully-available' loaded from '/home/luisreciomelero/.local/lib/python3.8/site-packages/chaosk8s/deployment/probes.py'
[36m[2021-04-11 15:03:51 DEBUG] [__init__:65][39m Using Kubernetes context: default
[36m[2021-04-11 15:03:51 DEBUG] [probes:92][39m Watching events for 30s
[36m[2021-04-11 15:03:51 DEBUG] [probes:98][39m Deployment 'ms-create-depl' ADDED: Ready Replicas 1 - Unavailable Replicas None - Desired Replicas 1
[36m[2021-04-11 15:03:51 DEBUG] [activity:180][39m   => succeeded with 'True'
[36m[2021-04-11 15:03:51 DEBUG] [__init__:355][39m No controls to apply on 'activity'
[36m[2021-04-11 15:03:51 DEBUG] [hypothesis:211][39m allowed tolerance is True
[32m[2021-04-11 15:03:51 INFO] [hypothesis:221][39m Steady state hypothesis is met!
[36m[2021-04-11 15:03:51 DEBUG] [__init__:355][39m No controls to apply on 'hypothesis'
[33m[2021-04-11 15:03:51 WARNING] [run:580][39m Rollbacks were explicitly requested to be played
[32m[2021-04-11 15:03:51 INFO] [run:809][39m Let's rollback...
[36m[2021-04-11 15:03:51 DEBUG] [__init__:355][39m No controls to apply on 'rollback'
[32m[2021-04-11 15:03:51 INFO] [rollback:28][39m Rollback: create-deployment
[36m[2021-04-11 15:03:51 DEBUG] [__init__:355][39m No controls to apply on 'activity'
[32m[2021-04-11 15:03:51 INFO] [activity:161][39m Action: create-deployment
[36m[2021-04-11 15:03:51 DEBUG] [python:34][39m Activity 'create-deployment' loaded from '/home/luisreciomelero/.local/lib/python3.8/site-packages/chaosk8s/deployment/actions.py'
[36m[2021-04-11 15:03:51 DEBUG] [__init__:65][39m Using Kubernetes context: default
[36m[2021-04-11 15:03:51 DEBUG] [activity:235][39m Activity failed
    Traceback (most recent call last):
      File "/home/luisreciomelero/.local/lib/python3.8/site-packages/chaoslib/provider/python.py", line 55, in run_python_activity
        return func(**arguments)
      File "/home/luisreciomelero/.local/lib/python3.8/site-packages/chaosk8s/deployment/actions.py", line 29, in create_deployment
        deployment = yaml.load(f.read())
      File "/home/luisreciomelero/.local/lib/python3.8/site-packages/yaml/__init__.py", line 114, in load
        return loader.get_single_data()
      File "/home/luisreciomelero/.local/lib/python3.8/site-packages/yaml/constructor.py", line 49, in get_single_data
        node = self.get_single_node()
      File "/home/luisreciomelero/.local/lib/python3.8/site-packages/yaml/composer.py", line 41, in get_single_node
        raise ComposerError("expected a single document in the stream",
    yaml.composer.ComposerError: expected a single document in the stream
      in "<unicode string>", line 2, column 1:
        apiVersion: apps/v1
        ^
    but found another document
      in "<unicode string>", line 52, column 1:
        ---
        ^
    
    During handling of the above exception, another exception occurred:
    
    Traceback (most recent call last):
      File "/home/luisreciomelero/.local/lib/python3.8/site-packages/chaoslib/activity.py", line 228, in run_activity
        result = run_python_activity(activity, configuration, secrets)
      File "/home/luisreciomelero/.local/lib/python3.8/site-packages/chaoslib/provider/python.py", line 57, in run_python_activity
        raise ActivityFailed(
      File "/home/luisreciomelero/.local/lib/python3.8/site-packages/chaoslib/provider/python.py", line 55, in run_python_activity
        return func(**arguments)
      File "/home/luisreciomelero/.local/lib/python3.8/site-packages/chaosk8s/deployment/actions.py", line 29, in create_deployment
        deployment = yaml.load(f.read())
      File "/home/luisreciomelero/.local/lib/python3.8/site-packages/yaml/__init__.py", line 114, in load
        return loader.get_single_data()
      File "/home/luisreciomelero/.local/lib/python3.8/site-packages/yaml/constructor.py", line 49, in get_single_data
        node = self.get_single_node()
      File "/home/luisreciomelero/.local/lib/python3.8/site-packages/yaml/composer.py", line 41, in get_single_node
        raise ComposerError("expected a single document in the stream",
    chaoslib.exceptions.ActivityFailed: yaml.composer.ComposerError: expected a single document in the stream
      in "<unicode string>", line 2, column 1:
        apiVersion: apps/v1
        ^
    but found another document
      in "<unicode string>", line 52, column 1:
        ---
        ^
[31m[2021-04-11 15:03:51 ERROR] [activity:188][39m   => failed: yaml.composer.ComposerError: expected a single document in the stream
      in "<unicode string>", line 2, column 1:
        apiVersion: apps/v1
        ^
    but found another document
      in "<unicode string>", line 52, column 1:
        ---
        ^
[36m[2021-04-11 15:03:51 DEBUG] [__init__:355][39m No controls to apply on 'activity'
[36m[2021-04-11 15:03:51 DEBUG] [__init__:355][39m No controls to apply on 'rollback'
[32m[2021-04-11 15:03:51 INFO] [run:421][39m Experiment ended with status: completed
[36m[2021-04-11 15:03:51 DEBUG] [__init__:355][39m No controls to apply on 'experiment'
[36m[2021-04-11 15:03:51 DEBUG] [__init__:72][39m Cleaning up controls
[36m[2021-04-11 15:03:51 DEBUG] [caching:42][39m Clearing activities cache
[36m[2021-04-11 15:05:41 DEBUG] [cli:73][39m ###############################################################################
[36m[2021-04-11 15:05:41 DEBUG] [cli:74][39m Running command 'run'
[36m[2021-04-11 15:05:41 DEBUG] [cli:78][39m Using settings file '/home/luisreciomelero/.chaostoolkit/settings.yaml'
[36m[2021-04-11 15:05:41 DEBUG] [settings:26][39m The Chaos Toolkit settings file could not be found at '/home/luisreciomelero/.chaostoolkit/settings.yaml'.
[36m[2021-04-11 15:05:41 DEBUG] [__init__:355][39m No controls to apply on 'loader'
[36m[2021-04-11 15:05:41 DEBUG] [__init__:355][39m No controls to apply on 'loader'
[36m[2021-04-11 15:05:41 DEBUG] [caching:25][39m Building activity cache...
[36m[2021-04-11 15:05:41 DEBUG] [caching:35][39m Cached 2 activities
[32m[2021-04-11 15:05:41 INFO] [experiment:47][39m Validating the experiment's syntax
[36m[2021-04-11 15:05:41 DEBUG] [configuration:54][39m Loading configuration...
[36m[2021-04-11 15:05:41 DEBUG] [secret:75][39m Loading secrets...
[36m[2021-04-11 15:05:41 DEBUG] [secret:92][39m Secrets loaded
[32m[2021-04-11 15:05:42 INFO] [experiment:96][39m Experiment looks valid
[36m[2021-04-11 15:05:42 DEBUG] [caching:42][39m Clearing activities cache
[36m[2021-04-11 15:05:42 DEBUG] [caching:25][39m Building activity cache...
[36m[2021-04-11 15:05:42 DEBUG] [caching:35][39m Cached 2 activities
[36m[2021-04-11 15:05:42 DEBUG] [configuration:54][39m Loading configuration...
[36m[2021-04-11 15:05:42 DEBUG] [secret:75][39m Loading secrets...
[36m[2021-04-11 15:05:42 DEBUG] [secret:92][39m Secrets loaded
[32m[2021-04-11 15:05:42 INFO] [run:323][39m Running experiment: Â¿QuÃ© ocurre cuando eliminamos el deployment que gestiona el microservicio create?
[36m[2021-04-11 15:05:42 DEBUG] [__init__:39][39m Initializing controls
[32m[2021-04-11 15:05:42 INFO] [run:342][39m Steady-state strategy: default
[32m[2021-04-11 15:05:42 INFO] [run:345][39m Rollbacks strategy: always
[36m[2021-04-11 15:05:42 DEBUG] [__init__:355][39m No controls to apply on 'experiment'
[36m[2021-04-11 15:05:42 DEBUG] [run:466][39m Running steady-state hypothesis before the method
[32m[2021-04-11 15:05:42 INFO] [hypothesis:183][39m Steady state hypothesis: Deployment available
[36m[2021-04-11 15:05:42 DEBUG] [__init__:355][39m No controls to apply on 'hypothesis'
[36m[2021-04-11 15:05:42 DEBUG] [__init__:355][39m No controls to apply on 'activity'
[32m[2021-04-11 15:05:42 INFO] [activity:161][39m Probe: deployment-fully-available
[36m[2021-04-11 15:05:42 DEBUG] [python:34][39m Activity 'deployment-fully-available' loaded from '/home/luisreciomelero/.local/lib/python3.8/site-packages/chaosk8s/deployment/probes.py'
[36m[2021-04-11 15:05:42 DEBUG] [__init__:65][39m Using Kubernetes context: default
[36m[2021-04-11 15:05:42 DEBUG] [probes:92][39m Watching events for 30s
[36m[2021-04-11 15:05:42 DEBUG] [probes:98][39m Deployment 'ms-create-depl' ADDED: Ready Replicas 1 - Unavailable Replicas None - Desired Replicas 1
[36m[2021-04-11 15:05:42 DEBUG] [activity:180][39m   => succeeded with 'True'
[36m[2021-04-11 15:05:42 DEBUG] [__init__:355][39m No controls to apply on 'activity'
[36m[2021-04-11 15:05:42 DEBUG] [hypothesis:211][39m allowed tolerance is True
[32m[2021-04-11 15:05:42 INFO] [hypothesis:221][39m Steady state hypothesis is met!
[36m[2021-04-11 15:05:42 DEBUG] [__init__:355][39m No controls to apply on 'hypothesis'
[32m[2021-04-11 15:05:42 INFO] [run:553][39m Playing your experiment's method now...
[36m[2021-04-11 15:05:42 DEBUG] [__init__:355][39m No controls to apply on 'method'
[36m[2021-04-11 15:05:42 DEBUG] [__init__:355][39m No controls to apply on 'activity'
[32m[2021-04-11 15:05:42 INFO] [activity:161][39m Action: delete-deployment
[36m[2021-04-11 15:05:42 DEBUG] [python:34][39m Activity 'delete-deployment' loaded from '/home/luisreciomelero/.local/lib/python3.8/site-packages/chaosk8s/deployment/actions.py'
[36m[2021-04-11 15:05:42 DEBUG] [__init__:65][39m Using Kubernetes context: default
[36m[2021-04-11 15:05:42 DEBUG] [actions:58][39m Found 0 deployments named 'ms-create-depl'
[36m[2021-04-11 15:05:42 DEBUG] [activity:182][39m   => succeeded without any result value
[32m[2021-04-11 15:05:42 INFO] [activity:198][39m Pausing after activity for 20s...
[36m[2021-04-11 15:06:02 DEBUG] [__init__:355][39m No controls to apply on 'activity'
[36m[2021-04-11 15:06:02 DEBUG] [__init__:355][39m No controls to apply on 'method'
[36m[2021-04-11 15:06:02 DEBUG] [run:496][39m Running steady-state hypothesis after the method
[32m[2021-04-11 15:06:02 INFO] [hypothesis:183][39m Steady state hypothesis: Deployment available
[36m[2021-04-11 15:06:02 DEBUG] [__init__:355][39m No controls to apply on 'hypothesis'
[36m[2021-04-11 15:06:02 DEBUG] [__init__:355][39m No controls to apply on 'activity'
[32m[2021-04-11 15:06:02 INFO] [activity:161][39m Probe: deployment-fully-available
[36m[2021-04-11 15:06:02 DEBUG] [python:34][39m Activity 'deployment-fully-available' loaded from '/home/luisreciomelero/.local/lib/python3.8/site-packages/chaosk8s/deployment/probes.py'
[36m[2021-04-11 15:06:02 DEBUG] [__init__:65][39m Using Kubernetes context: default
[36m[2021-04-11 15:06:02 DEBUG] [probes:92][39m Watching events for 30s
[36m[2021-04-11 15:06:02 DEBUG] [probes:98][39m Deployment 'ms-create-depl' ADDED: Ready Replicas 1 - Unavailable Replicas None - Desired Replicas 1
[36m[2021-04-11 15:06:02 DEBUG] [activity:180][39m   => succeeded with 'True'
[36m[2021-04-11 15:06:02 DEBUG] [__init__:355][39m No controls to apply on 'activity'
[36m[2021-04-11 15:06:02 DEBUG] [hypothesis:211][39m allowed tolerance is True
[32m[2021-04-11 15:06:02 INFO] [hypothesis:221][39m Steady state hypothesis is met!
[36m[2021-04-11 15:06:02 DEBUG] [__init__:355][39m No controls to apply on 'hypothesis'
[33m[2021-04-11 15:06:02 WARNING] [run:580][39m Rollbacks were explicitly requested to be played
[32m[2021-04-11 15:06:02 INFO] [run:809][39m Let's rollback...
[36m[2021-04-11 15:06:02 DEBUG] [__init__:355][39m No controls to apply on 'rollback'
[32m[2021-04-11 15:06:02 INFO] [rollback:25][39m No declared rollbacks, let's move on.
[36m[2021-04-11 15:06:02 DEBUG] [__init__:355][39m No controls to apply on 'rollback'
[32m[2021-04-11 15:06:02 INFO] [run:421][39m Experiment ended with status: completed
[36m[2021-04-11 15:06:02 DEBUG] [__init__:355][39m No controls to apply on 'experiment'
[36m[2021-04-11 15:06:02 DEBUG] [__init__:72][39m Cleaning up controls
[36m[2021-04-11 15:06:02 DEBUG] [caching:42][39m Clearing activities cache
[36m[2021-04-11 15:42:55 DEBUG] [cli:73][39m ###############################################################################
[36m[2021-04-11 15:42:55 DEBUG] [cli:74][39m Running command 'run'
[36m[2021-04-11 15:42:55 DEBUG] [cli:78][39m Using settings file '/home/luisreciomelero/.chaostoolkit/settings.yaml'
[36m[2021-04-11 15:42:56 DEBUG] [settings:26][39m The Chaos Toolkit settings file could not be found at '/home/luisreciomelero/.chaostoolkit/settings.yaml'.
[36m[2021-04-11 15:42:56 DEBUG] [__init__:355][39m No controls to apply on 'loader'
[36m[2021-04-11 15:42:56 DEBUG] [__init__:355][39m No controls to apply on 'loader'
[36m[2021-04-11 15:42:56 DEBUG] [caching:25][39m Building activity cache...
[36m[2021-04-11 15:42:56 DEBUG] [caching:35][39m Cached 1 activities
[32m[2021-04-11 15:42:56 INFO] [experiment:47][39m Validating the experiment's syntax
[36m[2021-04-11 15:42:56 DEBUG] [configuration:54][39m Loading configuration...
[36m[2021-04-11 15:42:56 DEBUG] [secret:75][39m Loading secrets...
[36m[2021-04-11 15:42:56 DEBUG] [secret:92][39m Secrets loaded
[32m[2021-04-11 15:42:56 INFO] [experiment:96][39m Experiment looks valid
[36m[2021-04-11 15:42:56 DEBUG] [caching:42][39m Clearing activities cache
[36m[2021-04-11 15:42:56 DEBUG] [caching:25][39m Building activity cache...
[36m[2021-04-11 15:42:56 DEBUG] [caching:35][39m Cached 1 activities
[36m[2021-04-11 15:42:56 DEBUG] [configuration:54][39m Loading configuration...
[36m[2021-04-11 15:42:56 DEBUG] [secret:75][39m Loading secrets...
[36m[2021-04-11 15:42:56 DEBUG] [secret:92][39m Secrets loaded
[32m[2021-04-11 15:42:56 INFO] [run:323][39m Running experiment: Â¿QuÃ© ocurre cuando eliminamos el deployment que gestiona el microservicio create?
[36m[2021-04-11 15:42:56 DEBUG] [__init__:39][39m Initializing controls
[32m[2021-04-11 15:42:56 INFO] [run:342][39m Steady-state strategy: default
[32m[2021-04-11 15:42:56 INFO] [run:345][39m Rollbacks strategy: default
[32m[2021-04-11 15:42:56 INFO] [run:350][39m No steady state hypothesis defined. That's ok, just exploring.
[36m[2021-04-11 15:42:56 DEBUG] [__init__:355][39m No controls to apply on 'experiment'
[32m[2021-04-11 15:42:56 INFO] [run:553][39m Playing your experiment's method now...
[36m[2021-04-11 15:42:56 DEBUG] [__init__:355][39m No controls to apply on 'method'
[36m[2021-04-11 15:42:56 DEBUG] [__init__:355][39m No controls to apply on 'activity'
[32m[2021-04-11 15:42:56 INFO] [activity:161][39m Action: delete-deployment
[36m[2021-04-11 15:42:56 DEBUG] [python:34][39m Activity 'delete-deployment' loaded from '/home/luisreciomelero/.local/lib/python3.8/site-packages/chaosk8s/deployment/actions.py'
[36m[2021-04-11 15:42:56 DEBUG] [__init__:65][39m Using Kubernetes context: default
[36m[2021-04-11 15:42:56 DEBUG] [actions:58][39m Found 0 deployments named 'ms-create-depl'
[36m[2021-04-11 15:42:56 DEBUG] [activity:182][39m   => succeeded without any result value
[36m[2021-04-11 15:42:56 DEBUG] [__init__:355][39m No controls to apply on 'activity'
[36m[2021-04-11 15:42:56 DEBUG] [__init__:355][39m No controls to apply on 'method'
[32m[2021-04-11 15:42:56 INFO] [run:809][39m Let's rollback...
[36m[2021-04-11 15:42:56 DEBUG] [__init__:355][39m No controls to apply on 'rollback'
[32m[2021-04-11 15:42:56 INFO] [rollback:25][39m No declared rollbacks, let's move on.
[36m[2021-04-11 15:42:56 DEBUG] [__init__:355][39m No controls to apply on 'rollback'
[32m[2021-04-11 15:42:56 INFO] [run:421][39m Experiment ended with status: completed
[36m[2021-04-11 15:42:56 DEBUG] [__init__:355][39m No controls to apply on 'experiment'
[36m[2021-04-11 15:42:56 DEBUG] [__init__:72][39m Cleaning up controls
[36m[2021-04-11 15:42:56 DEBUG] [caching:42][39m Clearing activities cache
[36m[2021-04-11 15:43:27 DEBUG] [cli:73][39m ###############################################################################
[36m[2021-04-11 15:43:27 DEBUG] [cli:74][39m Running command 'run'
[36m[2021-04-11 15:43:27 DEBUG] [cli:78][39m Using settings file '/home/luisreciomelero/.chaostoolkit/settings.yaml'
[36m[2021-04-11 15:43:28 DEBUG] [settings:26][39m The Chaos Toolkit settings file could not be found at '/home/luisreciomelero/.chaostoolkit/settings.yaml'.
[36m[2021-04-11 15:43:28 DEBUG] [__init__:355][39m No controls to apply on 'loader'
[36m[2021-04-11 15:43:28 DEBUG] [__init__:355][39m No controls to apply on 'loader'
[36m[2021-04-11 15:43:28 DEBUG] [caching:25][39m Building activity cache...
[36m[2021-04-11 15:43:28 DEBUG] [caching:35][39m Cached 1 activities
[32m[2021-04-11 15:43:28 INFO] [experiment:47][39m Validating the experiment's syntax
[36m[2021-04-11 15:43:28 DEBUG] [configuration:54][39m Loading configuration...
[36m[2021-04-11 15:43:28 DEBUG] [secret:75][39m Loading secrets...
[36m[2021-04-11 15:43:28 DEBUG] [secret:92][39m Secrets loaded
[32m[2021-04-11 15:43:28 INFO] [experiment:96][39m Experiment looks valid
[36m[2021-04-11 15:43:28 DEBUG] [caching:42][39m Clearing activities cache
[36m[2021-04-11 15:43:28 DEBUG] [caching:25][39m Building activity cache...
[36m[2021-04-11 15:43:28 DEBUG] [caching:35][39m Cached 1 activities
[36m[2021-04-11 15:43:28 DEBUG] [configuration:54][39m Loading configuration...
[36m[2021-04-11 15:43:28 DEBUG] [secret:75][39m Loading secrets...
[36m[2021-04-11 15:43:28 DEBUG] [secret:92][39m Secrets loaded
[32m[2021-04-11 15:43:28 INFO] [run:323][39m Running experiment: Â¿QuÃ© ocurre cuando eliminamos el deployment que gestiona el microservicio create?
[36m[2021-04-11 15:43:28 DEBUG] [__init__:39][39m Initializing controls
[32m[2021-04-11 15:43:28 INFO] [run:342][39m Steady-state strategy: default
[32m[2021-04-11 15:43:28 INFO] [run:345][39m Rollbacks strategy: default
[32m[2021-04-11 15:43:28 INFO] [run:350][39m No steady state hypothesis defined. That's ok, just exploring.
[36m[2021-04-11 15:43:28 DEBUG] [__init__:355][39m No controls to apply on 'experiment'
[32m[2021-04-11 15:43:28 INFO] [run:553][39m Playing your experiment's method now...
[36m[2021-04-11 15:43:28 DEBUG] [__init__:355][39m No controls to apply on 'method'
[36m[2021-04-11 15:43:28 DEBUG] [__init__:355][39m No controls to apply on 'activity'
[32m[2021-04-11 15:43:28 INFO] [activity:161][39m Action: delete-deployment
[36m[2021-04-11 15:43:28 DEBUG] [python:34][39m Activity 'delete-deployment' loaded from '/home/luisreciomelero/.local/lib/python3.8/site-packages/chaosk8s/deployment/actions.py'
[36m[2021-04-11 15:43:28 DEBUG] [__init__:65][39m Using Kubernetes context: default
[36m[2021-04-11 15:43:28 DEBUG] [actions:58][39m Found 0 deployments named 'ms-create-depl'
[36m[2021-04-11 15:43:28 DEBUG] [activity:182][39m   => succeeded without any result value
[36m[2021-04-11 15:43:28 DEBUG] [__init__:355][39m No controls to apply on 'activity'
[36m[2021-04-11 15:43:28 DEBUG] [__init__:355][39m No controls to apply on 'method'
[32m[2021-04-11 15:43:28 INFO] [run:809][39m Let's rollback...
[36m[2021-04-11 15:43:28 DEBUG] [__init__:355][39m No controls to apply on 'rollback'
[32m[2021-04-11 15:43:28 INFO] [rollback:25][39m No declared rollbacks, let's move on.
[36m[2021-04-11 15:43:28 DEBUG] [__init__:355][39m No controls to apply on 'rollback'
[32m[2021-04-11 15:43:28 INFO] [run:421][39m Experiment ended with status: completed
[36m[2021-04-11 15:43:28 DEBUG] [__init__:355][39m No controls to apply on 'experiment'
[36m[2021-04-11 15:43:28 DEBUG] [__init__:72][39m Cleaning up controls
[36m[2021-04-11 15:43:28 DEBUG] [caching:42][39m Clearing activities cache
[36m[2021-04-11 15:48:12 DEBUG] [cli:73][39m ###############################################################################
[36m[2021-04-11 15:48:12 DEBUG] [cli:74][39m Running command 'run'
[36m[2021-04-11 15:48:12 DEBUG] [cli:78][39m Using settings file '/home/luisreciomelero/.chaostoolkit/settings.yaml'
[36m[2021-04-11 15:48:13 DEBUG] [settings:26][39m The Chaos Toolkit settings file could not be found at '/home/luisreciomelero/.chaostoolkit/settings.yaml'.
[36m[2021-04-11 15:48:13 DEBUG] [__init__:355][39m No controls to apply on 'loader'
[36m[2021-04-11 15:48:13 DEBUG] [__init__:355][39m No controls to apply on 'loader'
[36m[2021-04-11 15:49:32 DEBUG] [cli:73][39m ###############################################################################
[36m[2021-04-11 15:49:32 DEBUG] [cli:74][39m Running command 'run'
[36m[2021-04-11 15:49:32 DEBUG] [cli:78][39m Using settings file '/home/luisreciomelero/.chaostoolkit/settings.yaml'
[36m[2021-04-11 15:49:33 DEBUG] [settings:26][39m The Chaos Toolkit settings file could not be found at '/home/luisreciomelero/.chaostoolkit/settings.yaml'.
[36m[2021-04-11 15:49:33 DEBUG] [__init__:355][39m No controls to apply on 'loader'
[36m[2021-04-11 15:49:33 DEBUG] [__init__:355][39m No controls to apply on 'loader'
[36m[2021-04-11 15:49:33 DEBUG] [caching:25][39m Building activity cache...
[36m[2021-04-11 15:49:33 DEBUG] [caching:35][39m Cached 1 activities
[32m[2021-04-11 15:49:33 INFO] [experiment:47][39m Validating the experiment's syntax
[36m[2021-04-11 15:49:33 DEBUG] [configuration:54][39m Loading configuration...
[36m[2021-04-11 15:49:33 DEBUG] [secret:75][39m Loading secrets...
[36m[2021-04-11 15:49:33 DEBUG] [secret:92][39m Secrets loaded
[32m[2021-04-11 15:49:33 INFO] [experiment:96][39m Experiment looks valid
[36m[2021-04-11 15:49:33 DEBUG] [caching:42][39m Clearing activities cache
[36m[2021-04-11 15:49:33 DEBUG] [caching:25][39m Building activity cache...
[36m[2021-04-11 15:49:33 DEBUG] [caching:35][39m Cached 1 activities
[36m[2021-04-11 15:49:33 DEBUG] [configuration:54][39m Loading configuration...
[36m[2021-04-11 15:49:33 DEBUG] [secret:75][39m Loading secrets...
[36m[2021-04-11 15:49:33 DEBUG] [secret:92][39m Secrets loaded
[32m[2021-04-11 15:49:33 INFO] [run:323][39m Running experiment: Do we remain available in face of pod going down?
[36m[2021-04-11 15:49:33 DEBUG] [__init__:39][39m Initializing controls
[32m[2021-04-11 15:49:33 INFO] [run:342][39m Steady-state strategy: default
[32m[2021-04-11 15:49:33 INFO] [run:345][39m Rollbacks strategy: default
[32m[2021-04-11 15:49:33 INFO] [run:350][39m No steady state hypothesis defined. That's ok, just exploring.
[36m[2021-04-11 15:49:33 DEBUG] [__init__:355][39m No controls to apply on 'experiment'
[32m[2021-04-11 15:49:33 INFO] [run:553][39m Playing your experiment's method now...
[36m[2021-04-11 15:49:33 DEBUG] [__init__:355][39m No controls to apply on 'method'
[36m[2021-04-11 15:49:33 DEBUG] [__init__:355][39m No controls to apply on 'activity'
[32m[2021-04-11 15:49:33 INFO] [activity:161][39m Action: delete-deployment
[36m[2021-04-11 15:49:33 DEBUG] [python:34][39m Activity 'delete-deployment' loaded from '/home/luisreciomelero/.local/lib/python3.8/site-packages/chaosk8s/deployment/actions.py'
[36m[2021-04-11 15:49:33 DEBUG] [__init__:65][39m Using Kubernetes context: default
[36m[2021-04-11 15:49:33 DEBUG] [actions:58][39m Found 0 deployments named 'ms-create-depl'
[36m[2021-04-11 15:49:33 DEBUG] [activity:182][39m   => succeeded without any result value
[36m[2021-04-11 15:49:33 DEBUG] [__init__:355][39m No controls to apply on 'activity'
[36m[2021-04-11 15:49:33 DEBUG] [__init__:355][39m No controls to apply on 'method'
[32m[2021-04-11 15:49:33 INFO] [run:809][39m Let's rollback...
[36m[2021-04-11 15:49:33 DEBUG] [__init__:355][39m No controls to apply on 'rollback'
[32m[2021-04-11 15:49:33 INFO] [rollback:25][39m No declared rollbacks, let's move on.
[36m[2021-04-11 15:49:33 DEBUG] [__init__:355][39m No controls to apply on 'rollback'
[32m[2021-04-11 15:49:33 INFO] [run:421][39m Experiment ended with status: completed
[36m[2021-04-11 15:49:33 DEBUG] [__init__:355][39m No controls to apply on 'experiment'
[36m[2021-04-11 15:49:33 DEBUG] [__init__:72][39m Cleaning up controls
[36m[2021-04-11 15:49:33 DEBUG] [caching:42][39m Clearing activities cache
[36m[2021-04-11 16:03:02 DEBUG] [cli:73][39m ###############################################################################
[36m[2021-04-11 16:03:02 DEBUG] [cli:74][39m Running command 'run'
[36m[2021-04-11 16:03:02 DEBUG] [cli:78][39m Using settings file '/home/luisreciomelero/.chaostoolkit/settings.yaml'
[36m[2021-04-11 16:03:02 DEBUG] [settings:26][39m The Chaos Toolkit settings file could not be found at '/home/luisreciomelero/.chaostoolkit/settings.yaml'.
[36m[2021-04-11 16:03:02 DEBUG] [__init__:355][39m No controls to apply on 'loader'
[36m[2021-04-11 16:03:02 DEBUG] [__init__:355][39m No controls to apply on 'loader'
[31m[2021-04-11 16:03:02 ERROR] [cli:164][39m Path "delete-dep.json" does not exist.
[36m[2021-04-11 16:03:02 DEBUG] [cli:165][39m Path "delete-dep.json" does not exist.
[36m[2021-04-11 16:03:07 DEBUG] [cli:73][39m ###############################################################################
[36m[2021-04-11 16:03:07 DEBUG] [cli:74][39m Running command 'run'
[36m[2021-04-11 16:03:07 DEBUG] [cli:78][39m Using settings file '/home/luisreciomelero/.chaostoolkit/settings.yaml'
[36m[2021-04-11 16:03:08 DEBUG] [settings:26][39m The Chaos Toolkit settings file could not be found at '/home/luisreciomelero/.chaostoolkit/settings.yaml'.
[36m[2021-04-11 16:03:08 DEBUG] [__init__:355][39m No controls to apply on 'loader'
[36m[2021-04-11 16:03:08 DEBUG] [__init__:355][39m No controls to apply on 'loader'
[36m[2021-04-11 16:03:08 DEBUG] [caching:25][39m Building activity cache...
[36m[2021-04-11 16:03:08 DEBUG] [caching:35][39m Cached 2 activities
[32m[2021-04-11 16:03:08 INFO] [experiment:47][39m Validating the experiment's syntax
[36m[2021-04-11 16:03:08 DEBUG] [configuration:54][39m Loading configuration...
[36m[2021-04-11 16:03:08 DEBUG] [secret:75][39m Loading secrets...
[36m[2021-04-11 16:03:08 DEBUG] [secret:92][39m Secrets loaded
[32m[2021-04-11 16:03:08 INFO] [experiment:96][39m Experiment looks valid
[36m[2021-04-11 16:03:08 DEBUG] [caching:42][39m Clearing activities cache
[36m[2021-04-11 16:03:08 DEBUG] [caching:25][39m Building activity cache...
[36m[2021-04-11 16:03:08 DEBUG] [caching:35][39m Cached 2 activities
[36m[2021-04-11 16:03:08 DEBUG] [configuration:54][39m Loading configuration...
[36m[2021-04-11 16:03:08 DEBUG] [secret:75][39m Loading secrets...
[36m[2021-04-11 16:03:08 DEBUG] [secret:92][39m Secrets loaded
[32m[2021-04-11 16:03:08 INFO] [run:323][39m Running experiment: Â¿QuÃ© ocurre cuando eliminamos el deployment que gestiona el microservicio create?
[36m[2021-04-11 16:03:08 DEBUG] [__init__:39][39m Initializing controls
[32m[2021-04-11 16:03:08 INFO] [run:342][39m Steady-state strategy: default
[32m[2021-04-11 16:03:08 INFO] [run:345][39m Rollbacks strategy: default
[36m[2021-04-11 16:03:08 DEBUG] [__init__:355][39m No controls to apply on 'experiment'
[36m[2021-04-11 16:03:08 DEBUG] [run:466][39m Running steady-state hypothesis before the method
[32m[2021-04-11 16:03:08 INFO] [hypothesis:183][39m Steady state hypothesis: Deployment available
[36m[2021-04-11 16:03:08 DEBUG] [__init__:355][39m No controls to apply on 'hypothesis'
[36m[2021-04-11 16:03:08 DEBUG] [__init__:355][39m No controls to apply on 'activity'
[32m[2021-04-11 16:03:08 INFO] [activity:161][39m Probe: deployment-fully-available
[36m[2021-04-11 16:03:08 DEBUG] [python:34][39m Activity 'deployment-fully-available' loaded from '/home/luisreciomelero/.local/lib/python3.8/site-packages/chaosk8s/deployment/probes.py'
[36m[2021-04-11 16:03:08 DEBUG] [__init__:65][39m Using Kubernetes context: default
[36m[2021-04-11 16:03:08 DEBUG] [probes:92][39m Watching events for 30s
[36m[2021-04-11 16:03:08 DEBUG] [probes:98][39m Deployment 'ms-create-depl' ADDED: Ready Replicas 1 - Unavailable Replicas None - Desired Replicas 1
[36m[2021-04-11 16:03:08 DEBUG] [activity:180][39m   => succeeded with 'True'
[36m[2021-04-11 16:03:08 DEBUG] [__init__:355][39m No controls to apply on 'activity'
[36m[2021-04-11 16:03:08 DEBUG] [hypothesis:211][39m allowed tolerance is True
[32m[2021-04-11 16:03:08 INFO] [hypothesis:221][39m Steady state hypothesis is met!
[36m[2021-04-11 16:03:08 DEBUG] [__init__:355][39m No controls to apply on 'hypothesis'
[32m[2021-04-11 16:03:08 INFO] [run:553][39m Playing your experiment's method now...
[36m[2021-04-11 16:03:08 DEBUG] [__init__:355][39m No controls to apply on 'method'
[36m[2021-04-11 16:03:08 DEBUG] [__init__:355][39m No controls to apply on 'activity'
[32m[2021-04-11 16:03:08 INFO] [activity:161][39m Action: delete-deployment
[36m[2021-04-11 16:03:08 DEBUG] [python:34][39m Activity 'delete-deployment' loaded from '/home/luisreciomelero/.local/lib/python3.8/site-packages/chaosk8s/deployment/actions.py'
[36m[2021-04-11 16:03:08 DEBUG] [__init__:65][39m Using Kubernetes context: default
[36m[2021-04-11 16:03:08 DEBUG] [actions:58][39m Found 0 deployments named 'ms-create-depl'
[36m[2021-04-11 16:03:08 DEBUG] [activity:182][39m   => succeeded without any result value
[32m[2021-04-11 16:03:08 INFO] [activity:198][39m Pausing after activity for 20s...
[36m[2021-04-11 16:03:24 DEBUG] [__init__:355][39m No controls to apply on 'activity'
[36m[2021-04-11 16:03:24 DEBUG] [__init__:355][39m No controls to apply on 'method'
[33m[2021-04-11 16:03:24 WARNING] [run:390][39m Received a termination signal (Ctrl-C)...
[32m[2021-04-11 16:03:24 INFO] [run:421][39m Experiment ended with status: interrupted
[36m[2021-04-11 16:03:24 DEBUG] [__init__:355][39m No controls to apply on 'experiment'
[36m[2021-04-11 16:03:24 DEBUG] [__init__:72][39m Cleaning up controls
[36m[2021-04-11 16:03:24 DEBUG] [caching:42][39m Clearing activities cache
[36m[2021-04-11 16:03:49 DEBUG] [cli:73][39m ###############################################################################
[36m[2021-04-11 16:03:49 DEBUG] [cli:74][39m Running command 'run'
[36m[2021-04-11 16:03:49 DEBUG] [cli:78][39m Using settings file '/home/luisreciomelero/.chaostoolkit/settings.yaml'
[36m[2021-04-11 16:03:50 DEBUG] [settings:26][39m The Chaos Toolkit settings file could not be found at '/home/luisreciomelero/.chaostoolkit/settings.yaml'.
[36m[2021-04-11 16:03:50 DEBUG] [__init__:355][39m No controls to apply on 'loader'
[36m[2021-04-11 16:03:50 DEBUG] [__init__:355][39m No controls to apply on 'loader'
[36m[2021-04-11 16:03:50 DEBUG] [caching:25][39m Building activity cache...
[36m[2021-04-11 16:03:50 DEBUG] [caching:35][39m Cached 2 activities
[32m[2021-04-11 16:03:50 INFO] [experiment:47][39m Validating the experiment's syntax
[36m[2021-04-11 16:03:50 DEBUG] [configuration:54][39m Loading configuration...
[36m[2021-04-11 16:03:50 DEBUG] [secret:75][39m Loading secrets...
[36m[2021-04-11 16:03:50 DEBUG] [secret:92][39m Secrets loaded
[32m[2021-04-11 16:03:50 INFO] [experiment:96][39m Experiment looks valid
[36m[2021-04-11 16:03:50 DEBUG] [caching:42][39m Clearing activities cache
[36m[2021-04-11 16:03:50 DEBUG] [caching:25][39m Building activity cache...
[36m[2021-04-11 16:03:50 DEBUG] [caching:35][39m Cached 2 activities
[36m[2021-04-11 16:03:50 DEBUG] [configuration:54][39m Loading configuration...
[36m[2021-04-11 16:03:50 DEBUG] [secret:75][39m Loading secrets...
[36m[2021-04-11 16:03:50 DEBUG] [secret:92][39m Secrets loaded
[32m[2021-04-11 16:03:50 INFO] [run:323][39m Running experiment: Â¿QuÃ© ocurre cuando eliminamos el deployment que gestiona el microservicio create?
[36m[2021-04-11 16:03:51 DEBUG] [__init__:39][39m Initializing controls
[32m[2021-04-11 16:03:51 INFO] [run:342][39m Steady-state strategy: default
[32m[2021-04-11 16:03:51 INFO] [run:345][39m Rollbacks strategy: default
[36m[2021-04-11 16:03:51 DEBUG] [__init__:355][39m No controls to apply on 'experiment'
[36m[2021-04-11 16:03:51 DEBUG] [run:466][39m Running steady-state hypothesis before the method
[32m[2021-04-11 16:03:51 INFO] [hypothesis:183][39m Steady state hypothesis: Deployment available
[36m[2021-04-11 16:03:51 DEBUG] [__init__:355][39m No controls to apply on 'hypothesis'
[36m[2021-04-11 16:03:51 DEBUG] [__init__:355][39m No controls to apply on 'activity'
[32m[2021-04-11 16:03:51 INFO] [activity:161][39m Probe: deployment-fully-available
[36m[2021-04-11 16:03:51 DEBUG] [python:34][39m Activity 'deployment-fully-available' loaded from '/home/luisreciomelero/.local/lib/python3.8/site-packages/chaosk8s/deployment/probes.py'
[36m[2021-04-11 16:03:51 DEBUG] [__init__:65][39m Using Kubernetes context: default
[36m[2021-04-11 16:03:51 DEBUG] [probes:92][39m Watching events for 30s
[36m[2021-04-11 16:03:51 DEBUG] [probes:98][39m Deployment 'ms-create-depl' ADDED: Ready Replicas 1 - Unavailable Replicas None - Desired Replicas 1
[36m[2021-04-11 16:03:51 DEBUG] [activity:180][39m   => succeeded with 'True'
[36m[2021-04-11 16:03:51 DEBUG] [__init__:355][39m No controls to apply on 'activity'
[36m[2021-04-11 16:03:51 DEBUG] [hypothesis:211][39m allowed tolerance is True
[32m[2021-04-11 16:03:51 INFO] [hypothesis:221][39m Steady state hypothesis is met!
[36m[2021-04-11 16:03:51 DEBUG] [__init__:355][39m No controls to apply on 'hypothesis'
[32m[2021-04-11 16:03:51 INFO] [run:553][39m Playing your experiment's method now...
[36m[2021-04-11 16:03:51 DEBUG] [__init__:355][39m No controls to apply on 'method'
[36m[2021-04-11 16:03:51 DEBUG] [__init__:355][39m No controls to apply on 'activity'
[32m[2021-04-11 16:03:51 INFO] [activity:161][39m Action: delete-deployment
[36m[2021-04-11 16:03:51 DEBUG] [python:34][39m Activity 'delete-deployment' loaded from '/home/luisreciomelero/.local/lib/python3.8/site-packages/chaosk8s/deployment/actions.py'
[36m[2021-04-11 16:03:51 DEBUG] [__init__:65][39m Using Kubernetes context: default
[36m[2021-04-11 16:03:51 DEBUG] [actions:58][39m Found 0 deployments named 'ms-create-depl'
[36m[2021-04-11 16:03:51 DEBUG] [activity:182][39m   => succeeded without any result value
[32m[2021-04-11 16:03:51 INFO] [activity:198][39m Pausing after activity for 20s...
[36m[2021-04-11 16:04:11 DEBUG] [__init__:355][39m No controls to apply on 'activity'
[36m[2021-04-11 16:04:11 DEBUG] [__init__:355][39m No controls to apply on 'method'
[36m[2021-04-11 16:04:11 DEBUG] [run:496][39m Running steady-state hypothesis after the method
[32m[2021-04-11 16:04:11 INFO] [hypothesis:183][39m Steady state hypothesis: Deployment available
[36m[2021-04-11 16:04:11 DEBUG] [__init__:355][39m No controls to apply on 'hypothesis'
[36m[2021-04-11 16:04:11 DEBUG] [__init__:355][39m No controls to apply on 'activity'
[32m[2021-04-11 16:04:11 INFO] [activity:161][39m Probe: deployment-fully-available
[36m[2021-04-11 16:04:11 DEBUG] [python:34][39m Activity 'deployment-fully-available' loaded from '/home/luisreciomelero/.local/lib/python3.8/site-packages/chaosk8s/deployment/probes.py'
[36m[2021-04-11 16:04:11 DEBUG] [__init__:65][39m Using Kubernetes context: default
[36m[2021-04-11 16:04:11 DEBUG] [probes:92][39m Watching events for 30s
[36m[2021-04-11 16:04:11 DEBUG] [probes:98][39m Deployment 'ms-create-depl' ADDED: Ready Replicas 1 - Unavailable Replicas None - Desired Replicas 1
[36m[2021-04-11 16:04:11 DEBUG] [activity:180][39m   => succeeded with 'True'
[36m[2021-04-11 16:04:11 DEBUG] [__init__:355][39m No controls to apply on 'activity'
[36m[2021-04-11 16:04:11 DEBUG] [hypothesis:211][39m allowed tolerance is True
[32m[2021-04-11 16:04:11 INFO] [hypothesis:221][39m Steady state hypothesis is met!
[36m[2021-04-11 16:04:11 DEBUG] [__init__:355][39m No controls to apply on 'hypothesis'
[32m[2021-04-11 16:04:11 INFO] [run:809][39m Let's rollback...
[36m[2021-04-11 16:04:11 DEBUG] [__init__:355][39m No controls to apply on 'rollback'
[32m[2021-04-11 16:04:11 INFO] [rollback:28][39m Rollback: create-deployment
[36m[2021-04-11 16:04:11 DEBUG] [__init__:355][39m No controls to apply on 'activity'
[32m[2021-04-11 16:04:11 INFO] [activity:161][39m Action: create-deployment
[36m[2021-04-11 16:04:11 DEBUG] [python:34][39m Activity 'create-deployment' loaded from '/home/luisreciomelero/.local/lib/python3.8/site-packages/chaosk8s/deployment/actions.py'
[36m[2021-04-11 16:04:11 DEBUG] [__init__:65][39m Using Kubernetes context: default
[36m[2021-04-11 16:04:11 DEBUG] [activity:235][39m Activity failed
    Traceback (most recent call last):
      File "/home/luisreciomelero/.local/lib/python3.8/site-packages/chaoslib/provider/python.py", line 55, in run_python_activity
        return func(**arguments)
      File "/home/luisreciomelero/.local/lib/python3.8/site-packages/chaosk8s/deployment/actions.py", line 29, in create_deployment
        deployment = yaml.load(f.read())
      File "/home/luisreciomelero/.local/lib/python3.8/site-packages/yaml/__init__.py", line 114, in load
        return loader.get_single_data()
      File "/home/luisreciomelero/.local/lib/python3.8/site-packages/yaml/constructor.py", line 49, in get_single_data
        node = self.get_single_node()
      File "/home/luisreciomelero/.local/lib/python3.8/site-packages/yaml/composer.py", line 41, in get_single_node
        raise ComposerError("expected a single document in the stream",
    yaml.composer.ComposerError: expected a single document in the stream
      in "<unicode string>", line 2, column 1:
        apiVersion: apps/v1
        ^
    but found another document
      in "<unicode string>", line 52, column 1:
        ---
        ^
    
    During handling of the above exception, another exception occurred:
    
    Traceback (most recent call last):
      File "/home/luisreciomelero/.local/lib/python3.8/site-packages/chaoslib/activity.py", line 228, in run_activity
        result = run_python_activity(activity, configuration, secrets)
      File "/home/luisreciomelero/.local/lib/python3.8/site-packages/chaoslib/provider/python.py", line 57, in run_python_activity
        raise ActivityFailed(
      File "/home/luisreciomelero/.local/lib/python3.8/site-packages/chaoslib/provider/python.py", line 55, in run_python_activity
        return func(**arguments)
      File "/home/luisreciomelero/.local/lib/python3.8/site-packages/chaosk8s/deployment/actions.py", line 29, in create_deployment
        deployment = yaml.load(f.read())
      File "/home/luisreciomelero/.local/lib/python3.8/site-packages/yaml/__init__.py", line 114, in load
        return loader.get_single_data()
      File "/home/luisreciomelero/.local/lib/python3.8/site-packages/yaml/constructor.py", line 49, in get_single_data
        node = self.get_single_node()
      File "/home/luisreciomelero/.local/lib/python3.8/site-packages/yaml/composer.py", line 41, in get_single_node
        raise ComposerError("expected a single document in the stream",
    chaoslib.exceptions.ActivityFailed: yaml.composer.ComposerError: expected a single document in the stream
      in "<unicode string>", line 2, column 1:
        apiVersion: apps/v1
        ^
    but found another document
      in "<unicode string>", line 52, column 1:
        ---
        ^
[31m[2021-04-11 16:04:11 ERROR] [activity:188][39m   => failed: yaml.composer.ComposerError: expected a single document in the stream
      in "<unicode string>", line 2, column 1:
        apiVersion: apps/v1
        ^
    but found another document
      in "<unicode string>", line 52, column 1:
        ---
        ^
[36m[2021-04-11 16:04:11 DEBUG] [__init__:355][39m No controls to apply on 'activity'
[36m[2021-04-11 16:04:11 DEBUG] [__init__:355][39m No controls to apply on 'rollback'
[32m[2021-04-11 16:04:11 INFO] [run:421][39m Experiment ended with status: completed
[36m[2021-04-11 16:04:11 DEBUG] [__init__:355][39m No controls to apply on 'experiment'
[36m[2021-04-11 16:04:11 DEBUG] [__init__:72][39m Cleaning up controls
[36m[2021-04-11 16:04:11 DEBUG] [caching:42][39m Clearing activities cache
[36m[2021-04-18 21:15:55 DEBUG] [cli:73][39m ###############################################################################
[36m[2021-04-18 21:15:56 DEBUG] [cli:74][39m Running command 'run'
[36m[2021-04-18 21:15:56 DEBUG] [cli:78][39m Using settings file '/home/luisreciomelero/.chaostoolkit/settings.yaml'
[36m[2021-04-18 21:15:57 DEBUG] [__init__:167][39m Loading global control 'chaosiq-cloud'
[36m[2021-04-18 21:15:57 DEBUG] [__init__:365][39m Applying before-control 'chaosiq-cloud' on 'loader'
[36m[2021-04-18 21:15:57 DEBUG] [python:166][39m Control 'before_loading_experiment_control' loaded from '/home/luisreciomelero/.local/lib/python3.8/site-packages/chaoscloud/controls.py'
[36m[2021-04-18 21:15:57 DEBUG] [workspace:85][39m The ChaosIQ workspace file could not be found at '.chaosiq'.
[36m[2021-04-18 21:15:57 DEBUG] [__init__:365][39m Applying after-control 'chaosiq-cloud' on 'loader'
[36m[2021-04-18 21:15:57 DEBUG] [python:166][39m Control 'after_loading_experiment_control' loaded from '/home/luisreciomelero/.local/lib/python3.8/site-packages/chaoscloud/controls.py'
[36m[2021-04-18 21:15:57 DEBUG] [caching:25][39m Building activity cache...
[36m[2021-04-18 21:15:57 DEBUG] [caching:35][39m Cached 2 activities
[32m[2021-04-18 21:15:57 INFO] [experiment:47][39m Validating the experiment's syntax
[36m[2021-04-18 21:15:57 DEBUG] [configuration:54][39m Loading configuration...
[36m[2021-04-18 21:15:57 DEBUG] [secret:75][39m Loading secrets...
[36m[2021-04-18 21:15:57 DEBUG] [secret:92][39m Secrets loaded
[36m[2021-04-18 21:15:57 DEBUG] [caching:42][39m Clearing activities cache
[31m[2021-04-18 21:15:57 ERROR] [cli:174][39m required argument 'name' is missing from activity 'deployment_fully_available'
[36m[2021-04-18 21:15:57 DEBUG] [cli:175][39m required argument 'name' is missing from activity 'deployment_fully_available'
[36m[2021-04-18 21:17:21 DEBUG] [cli:73][39m ###############################################################################
[36m[2021-04-18 21:17:21 DEBUG] [cli:74][39m Running command 'run'
[36m[2021-04-18 21:17:21 DEBUG] [cli:78][39m Using settings file '/home/luisreciomelero/.chaostoolkit/settings.yaml'
[36m[2021-04-18 21:17:22 DEBUG] [__init__:167][39m Loading global control 'chaosiq-cloud'
[36m[2021-04-18 21:17:22 DEBUG] [__init__:365][39m Applying before-control 'chaosiq-cloud' on 'loader'
[36m[2021-04-18 21:17:22 DEBUG] [python:166][39m Control 'before_loading_experiment_control' loaded from '/home/luisreciomelero/.local/lib/python3.8/site-packages/chaoscloud/controls.py'
[36m[2021-04-18 21:17:22 DEBUG] [workspace:85][39m The ChaosIQ workspace file could not be found at '.chaosiq'.
[36m[2021-04-18 21:17:22 DEBUG] [__init__:365][39m Applying after-control 'chaosiq-cloud' on 'loader'
[36m[2021-04-18 21:17:22 DEBUG] [python:166][39m Control 'after_loading_experiment_control' loaded from '/home/luisreciomelero/.local/lib/python3.8/site-packages/chaoscloud/controls.py'
[36m[2021-04-18 21:17:22 DEBUG] [caching:25][39m Building activity cache...
[36m[2021-04-18 21:17:22 DEBUG] [caching:35][39m Cached 2 activities
[32m[2021-04-18 21:17:22 INFO] [experiment:47][39m Validating the experiment's syntax
[36m[2021-04-18 21:17:22 DEBUG] [configuration:54][39m Loading configuration...
[36m[2021-04-18 21:17:22 DEBUG] [secret:75][39m Loading secrets...
[36m[2021-04-18 21:17:22 DEBUG] [secret:92][39m Secrets loaded
[36m[2021-04-18 21:17:22 DEBUG] [caching:42][39m Clearing activities cache
[31m[2021-04-18 21:17:22 ERROR] [cli:174][39m required argument 'name' is missing from activity 'deployment_fully_available'
[36m[2021-04-18 21:17:22 DEBUG] [cli:175][39m required argument 'name' is missing from activity 'deployment_fully_available'
[36m[2021-04-18 21:17:33 DEBUG] [cli:73][39m ###############################################################################
[36m[2021-04-18 21:17:33 DEBUG] [cli:74][39m Running command 'run'
[36m[2021-04-18 21:17:33 DEBUG] [cli:78][39m Using settings file '/home/luisreciomelero/.chaostoolkit/settings.yaml'
[36m[2021-04-18 21:17:34 DEBUG] [__init__:167][39m Loading global control 'chaosiq-cloud'
[36m[2021-04-18 21:17:34 DEBUG] [__init__:365][39m Applying before-control 'chaosiq-cloud' on 'loader'
[36m[2021-04-18 21:17:34 DEBUG] [python:166][39m Control 'before_loading_experiment_control' loaded from '/home/luisreciomelero/.local/lib/python3.8/site-packages/chaoscloud/controls.py'
[36m[2021-04-18 21:17:34 DEBUG] [workspace:85][39m The ChaosIQ workspace file could not be found at '.chaosiq'.
[36m[2021-04-18 21:17:34 DEBUG] [__init__:365][39m Applying after-control 'chaosiq-cloud' on 'loader'
[36m[2021-04-18 21:17:34 DEBUG] [python:166][39m Control 'after_loading_experiment_control' loaded from '/home/luisreciomelero/.local/lib/python3.8/site-packages/chaoscloud/controls.py'
[36m[2021-04-18 21:17:34 DEBUG] [caching:25][39m Building activity cache...
[36m[2021-04-18 21:17:34 DEBUG] [caching:35][39m Cached 2 activities
[32m[2021-04-18 21:17:34 INFO] [experiment:47][39m Validating the experiment's syntax
[36m[2021-04-18 21:17:34 DEBUG] [configuration:54][39m Loading configuration...
[36m[2021-04-18 21:17:34 DEBUG] [secret:75][39m Loading secrets...
[36m[2021-04-18 21:17:34 DEBUG] [secret:92][39m Secrets loaded
[36m[2021-04-18 21:17:35 DEBUG] [caching:42][39m Clearing activities cache
[31m[2021-04-18 21:17:35 ERROR] [cli:174][39m required argument 'name' is missing from activity 'deployment_fully_available'
[36m[2021-04-18 21:17:35 DEBUG] [cli:175][39m required argument 'name' is missing from activity 'deployment_fully_available'
[36m[2021-04-18 21:18:21 DEBUG] [cli:73][39m ###############################################################################
[36m[2021-04-18 21:18:21 DEBUG] [cli:74][39m Running command 'run'
[36m[2021-04-18 21:18:21 DEBUG] [cli:78][39m Using settings file '/home/luisreciomelero/.chaostoolkit/settings.yaml'
[36m[2021-04-18 21:18:22 DEBUG] [__init__:167][39m Loading global control 'chaosiq-cloud'
[36m[2021-04-18 21:18:22 DEBUG] [__init__:365][39m Applying before-control 'chaosiq-cloud' on 'loader'
[36m[2021-04-18 21:18:22 DEBUG] [python:166][39m Control 'before_loading_experiment_control' loaded from '/home/luisreciomelero/.local/lib/python3.8/site-packages/chaoscloud/controls.py'
[36m[2021-04-18 21:18:22 DEBUG] [workspace:85][39m The ChaosIQ workspace file could not be found at '.chaosiq'.
[36m[2021-04-18 21:18:22 DEBUG] [__init__:365][39m Applying after-control 'chaosiq-cloud' on 'loader'
[36m[2021-04-18 21:18:22 DEBUG] [python:166][39m Control 'after_loading_experiment_control' loaded from '/home/luisreciomelero/.local/lib/python3.8/site-packages/chaoscloud/controls.py'
[36m[2021-04-18 21:18:22 DEBUG] [caching:25][39m Building activity cache...
[36m[2021-04-18 21:18:22 DEBUG] [caching:35][39m Cached 2 activities
[32m[2021-04-18 21:18:22 INFO] [experiment:47][39m Validating the experiment's syntax
[36m[2021-04-18 21:18:22 DEBUG] [configuration:54][39m Loading configuration...
[36m[2021-04-18 21:18:22 DEBUG] [secret:75][39m Loading secrets...
[36m[2021-04-18 21:18:22 DEBUG] [secret:92][39m Secrets loaded
[36m[2021-04-18 21:18:22 DEBUG] [caching:42][39m Clearing activities cache
[31m[2021-04-18 21:18:22 ERROR] [cli:174][39m required argument 'name' is missing from activity 'deployment_fully_available'
[36m[2021-04-18 21:18:22 DEBUG] [cli:175][39m required argument 'name' is missing from activity 'deployment_fully_available'
[36m[2021-04-18 21:18:28 DEBUG] [cli:73][39m ###############################################################################
[36m[2021-04-18 21:18:28 DEBUG] [cli:74][39m Running command 'run'
[36m[2021-04-18 21:18:28 DEBUG] [cli:78][39m Using settings file '/home/luisreciomelero/.chaostoolkit/settings.yaml'
[36m[2021-04-18 21:18:43 DEBUG] [cli:73][39m ###############################################################################
[36m[2021-04-18 21:18:43 DEBUG] [cli:74][39m Running command 'run'
[36m[2021-04-18 21:18:43 DEBUG] [cli:78][39m Using settings file '/home/luisreciomelero/.chaostoolkit/settings.yaml'
[36m[2021-04-18 21:18:44 DEBUG] [__init__:167][39m Loading global control 'chaosiq-cloud'
[36m[2021-04-18 21:18:44 DEBUG] [__init__:365][39m Applying before-control 'chaosiq-cloud' on 'loader'
[36m[2021-04-18 21:18:44 DEBUG] [python:166][39m Control 'before_loading_experiment_control' loaded from '/home/luisreciomelero/.local/lib/python3.8/site-packages/chaoscloud/controls.py'
[36m[2021-04-18 21:18:44 DEBUG] [workspace:85][39m The ChaosIQ workspace file could not be found at '.chaosiq'.
[36m[2021-04-18 21:18:44 DEBUG] [__init__:365][39m Applying after-control 'chaosiq-cloud' on 'loader'
[36m[2021-04-18 21:18:44 DEBUG] [python:166][39m Control 'after_loading_experiment_control' loaded from '/home/luisreciomelero/.local/lib/python3.8/site-packages/chaoscloud/controls.py'
[36m[2021-04-18 21:18:44 DEBUG] [caching:25][39m Building activity cache...
[36m[2021-04-18 21:18:44 DEBUG] [caching:35][39m Cached 2 activities
[32m[2021-04-18 21:18:44 INFO] [experiment:47][39m Validating the experiment's syntax
[36m[2021-04-18 21:18:44 DEBUG] [configuration:54][39m Loading configuration...
[36m[2021-04-18 21:18:44 DEBUG] [secret:75][39m Loading secrets...
[36m[2021-04-18 21:18:44 DEBUG] [secret:92][39m Secrets loaded
[36m[2021-04-18 21:18:45 DEBUG] [caching:42][39m Clearing activities cache
[31m[2021-04-18 21:18:45 ERROR] [cli:174][39m required argument 'name' is missing from activity 'deployment_fully_available'
[36m[2021-04-18 21:18:45 DEBUG] [cli:175][39m required argument 'name' is missing from activity 'deployment_fully_available'
[36m[2021-04-18 21:19:37 DEBUG] [cli:73][39m ###############################################################################
[36m[2021-04-18 21:19:37 DEBUG] [cli:74][39m Running command 'run'
[36m[2021-04-18 21:19:37 DEBUG] [cli:78][39m Using settings file '/home/luisreciomelero/.chaostoolkit/settings.yaml'
[36m[2021-04-18 21:19:38 DEBUG] [__init__:167][39m Loading global control 'chaosiq-cloud'
[36m[2021-04-18 21:19:38 DEBUG] [__init__:365][39m Applying before-control 'chaosiq-cloud' on 'loader'
[36m[2021-04-18 21:19:38 DEBUG] [python:166][39m Control 'before_loading_experiment_control' loaded from '/home/luisreciomelero/.local/lib/python3.8/site-packages/chaoscloud/controls.py'
[36m[2021-04-18 21:19:38 DEBUG] [workspace:85][39m The ChaosIQ workspace file could not be found at '.chaosiq'.
[36m[2021-04-18 21:19:38 DEBUG] [__init__:365][39m Applying after-control 'chaosiq-cloud' on 'loader'
[36m[2021-04-18 21:19:38 DEBUG] [python:166][39m Control 'after_loading_experiment_control' loaded from '/home/luisreciomelero/.local/lib/python3.8/site-packages/chaoscloud/controls.py'
[36m[2021-04-18 21:19:38 DEBUG] [caching:25][39m Building activity cache...
[36m[2021-04-18 21:19:38 DEBUG] [caching:35][39m Cached 2 activities
[32m[2021-04-18 21:19:38 INFO] [experiment:47][39m Validating the experiment's syntax
[36m[2021-04-18 21:19:38 DEBUG] [configuration:54][39m Loading configuration...
[36m[2021-04-18 21:19:38 DEBUG] [secret:75][39m Loading secrets...
[36m[2021-04-18 21:19:38 DEBUG] [secret:92][39m Secrets loaded
[36m[2021-04-18 21:19:38 DEBUG] [caching:42][39m Clearing activities cache
[31m[2021-04-18 21:19:38 ERROR] [cli:174][39m required argument 'name' is missing from activity 'deployment_fully_available'
[36m[2021-04-18 21:19:38 DEBUG] [cli:175][39m required argument 'name' is missing from activity 'deployment_fully_available'
