[36m[2021-05-21 19:40:58 DEBUG] [cli:73][39m ###############################################################################
[36m[2021-05-21 19:40:58 DEBUG] [cli:74][39m Running command 'run'
[36m[2021-05-21 19:40:58 DEBUG] [cli:78][39m Using settings file '/home/luisreciomelero/.chaostoolkit/settings.yaml'
[36m[2021-05-21 19:40:59 DEBUG] [__init__:167][39m Loading global control 'chaosiq-cloud'
[36m[2021-05-21 19:40:59 DEBUG] [__init__:365][39m Applying before-control 'chaosiq-cloud' on 'loader'
[36m[2021-05-21 19:40:59 DEBUG] [python:166][39m Control 'before_loading_experiment_control' loaded from '/home/luisreciomelero/.local/lib/python3.8/site-packages/chaoscloud/controls.py'
[36m[2021-05-21 19:40:59 DEBUG] [__init__:365][39m Applying after-control 'chaosiq-cloud' on 'loader'
[36m[2021-05-21 19:40:59 DEBUG] [python:166][39m Control 'after_loading_experiment_control' loaded from '/home/luisreciomelero/.local/lib/python3.8/site-packages/chaoscloud/controls.py'
[31m[2021-05-21 19:40:59 ERROR] [cli:164][39m Path "./../chaos/experiments/pod-experiments/terminate-pods/running-and-ready/terminate-mg-pod-ssh-running-and-ready.yaml" does not exist.
[36m[2021-05-21 19:40:59 DEBUG] [cli:165][39m Path "./../chaos/experiments/pod-experiments/terminate-pods/running-and-ready/terminate-mg-pod-ssh-running-and-ready.yaml" does not exist.
[36m[2021-05-21 19:41:10 DEBUG] [cli:73][39m ###############################################################################
[36m[2021-05-21 19:41:10 DEBUG] [cli:74][39m Running command 'run'
[36m[2021-05-21 19:41:10 DEBUG] [cli:78][39m Using settings file '/home/luisreciomelero/.chaostoolkit/settings.yaml'
[36m[2021-05-21 19:41:11 DEBUG] [__init__:167][39m Loading global control 'chaosiq-cloud'
[36m[2021-05-21 19:41:11 DEBUG] [__init__:365][39m Applying before-control 'chaosiq-cloud' on 'loader'
[36m[2021-05-21 19:41:11 DEBUG] [python:166][39m Control 'before_loading_experiment_control' loaded from '/home/luisreciomelero/.local/lib/python3.8/site-packages/chaoscloud/controls.py'
[36m[2021-05-21 19:41:11 DEBUG] [workspace:85][39m The ChaosIQ workspace file could not be found at '../../chaos/experiments/pod-experiments/terminate-pods/running-and-ready/.chaosiq'.
[36m[2021-05-21 19:41:11 DEBUG] [__init__:365][39m Applying after-control 'chaosiq-cloud' on 'loader'
[36m[2021-05-21 19:41:11 DEBUG] [python:166][39m Control 'after_loading_experiment_control' loaded from '/home/luisreciomelero/.local/lib/python3.8/site-packages/chaoscloud/controls.py'
[36m[2021-05-21 19:41:11 DEBUG] [caching:25][39m Building activity cache...
[36m[2021-05-21 19:41:11 DEBUG] [caching:35][39m Cached 5 activities
[32m[2021-05-21 19:41:11 INFO] [experiment:47][39m Validating the experiment's syntax
[36m[2021-05-21 19:41:11 DEBUG] [configuration:54][39m Loading configuration...
[36m[2021-05-21 19:41:11 DEBUG] [secret:75][39m Loading secrets...
[36m[2021-05-21 19:41:11 DEBUG] [secret:92][39m Secrets loaded
[36m[2021-05-21 19:41:12 DEBUG] [caching:42][39m Clearing activities cache
[36m[2021-05-21 19:42:28 DEBUG] [cli:73][39m ###############################################################################
[36m[2021-05-21 19:42:28 DEBUG] [cli:74][39m Running command 'run'
[36m[2021-05-21 19:42:28 DEBUG] [cli:78][39m Using settings file '/home/luisreciomelero/.chaostoolkit/settings.yaml'
[36m[2021-05-21 19:42:29 DEBUG] [__init__:167][39m Loading global control 'chaosiq-cloud'
[36m[2021-05-21 19:42:29 DEBUG] [__init__:365][39m Applying before-control 'chaosiq-cloud' on 'loader'
[36m[2021-05-21 19:42:29 DEBUG] [python:166][39m Control 'before_loading_experiment_control' loaded from '/home/luisreciomelero/.local/lib/python3.8/site-packages/chaoscloud/controls.py'
[36m[2021-05-21 19:42:29 DEBUG] [workspace:85][39m The ChaosIQ workspace file could not be found at '../../chaos/experiments/pod-experiments/terminate-pods/running-and-ready/.chaosiq'.
[36m[2021-05-21 19:42:29 DEBUG] [__init__:365][39m Applying after-control 'chaosiq-cloud' on 'loader'
[36m[2021-05-21 19:42:29 DEBUG] [python:166][39m Control 'after_loading_experiment_control' loaded from '/home/luisreciomelero/.local/lib/python3.8/site-packages/chaoscloud/controls.py'
[36m[2021-05-21 19:42:29 DEBUG] [caching:25][39m Building activity cache...
[36m[2021-05-21 19:42:29 DEBUG] [caching:35][39m Cached 5 activities
[32m[2021-05-21 19:42:29 INFO] [experiment:47][39m Validating the experiment's syntax
[36m[2021-05-21 19:42:29 DEBUG] [configuration:54][39m Loading configuration...
[36m[2021-05-21 19:42:29 DEBUG] [secret:75][39m Loading secrets...
[36m[2021-05-21 19:42:29 DEBUG] [secret:92][39m Secrets loaded
[36m[2021-05-21 19:42:29 DEBUG] [caching:42][39m Clearing activities cache
[36m[2021-05-21 19:43:03 DEBUG] [cli:73][39m ###############################################################################
[36m[2021-05-21 19:43:03 DEBUG] [cli:74][39m Running command 'run'
[36m[2021-05-21 19:43:03 DEBUG] [cli:78][39m Using settings file '/home/luisreciomelero/.chaostoolkit/settings.yaml'
[36m[2021-05-21 19:43:04 DEBUG] [__init__:167][39m Loading global control 'chaosiq-cloud'
[36m[2021-05-21 19:43:04 DEBUG] [__init__:365][39m Applying before-control 'chaosiq-cloud' on 'loader'
[36m[2021-05-21 19:43:04 DEBUG] [python:166][39m Control 'before_loading_experiment_control' loaded from '/home/luisreciomelero/.local/lib/python3.8/site-packages/chaoscloud/controls.py'
[36m[2021-05-21 19:43:04 DEBUG] [workspace:85][39m The ChaosIQ workspace file could not be found at '../../chaos/experiments/pod-experiments/terminate-pods/running-and-ready/.chaosiq'.
[36m[2021-05-21 19:43:04 DEBUG] [__init__:365][39m Applying after-control 'chaosiq-cloud' on 'loader'
[36m[2021-05-21 19:43:04 DEBUG] [python:166][39m Control 'after_loading_experiment_control' loaded from '/home/luisreciomelero/.local/lib/python3.8/site-packages/chaoscloud/controls.py'
[36m[2021-05-21 19:43:04 DEBUG] [caching:25][39m Building activity cache...
[36m[2021-05-21 19:43:04 DEBUG] [caching:35][39m Cached 5 activities
[32m[2021-05-21 19:43:04 INFO] [experiment:47][39m Validating the experiment's syntax
[36m[2021-05-21 19:43:04 DEBUG] [configuration:54][39m Loading configuration...
[36m[2021-05-21 19:43:04 DEBUG] [secret:75][39m Loading secrets...
[36m[2021-05-21 19:43:04 DEBUG] [secret:92][39m Secrets loaded
[32m[2021-05-21 19:43:06 INFO] [experiment:96][39m Experiment looks valid
[36m[2021-05-21 19:43:06 DEBUG] [caching:42][39m Clearing activities cache
[36m[2021-05-21 19:43:06 DEBUG] [caching:25][39m Building activity cache...
[36m[2021-05-21 19:43:06 DEBUG] [caching:35][39m Cached 5 activities
[36m[2021-05-21 19:43:06 DEBUG] [configuration:54][39m Loading configuration...
[36m[2021-05-21 19:43:06 DEBUG] [secret:75][39m Loading secrets...
[36m[2021-05-21 19:43:06 DEBUG] [secret:92][39m Secrets loaded
[32m[2021-05-21 19:43:06 INFO] [run:323][39m Running experiment: Â¿QuÃ© ocurre cuando eliminamos el pod donde se ejecuta el microgateway?
[36m[2021-05-21 19:43:06 DEBUG] [__init__:136][39m Initializing global control 'chaosiq-cloud'
[36m[2021-05-21 19:43:06 DEBUG] [python:166][39m Control 'configure_control' loaded from '/home/luisreciomelero/.local/lib/python3.8/site-packages/chaoscloud/controls.py'
[33m[2021-05-21 19:43:09 WARNING] [execution:62][39m Execution failed to be published: Internal Server Error
[36m[2021-05-21 19:43:09 DEBUG] [workspace:147][39m Registering experiment 'terminate-mg-pod-ssh-running-and-ready.yaml' with ID 'd3bc65ca-3b4b-4fbf-85b9-e1cb420da303' for organization '846e69e0-c776-46c9-a431-a7de0487556e' and team 'ad7ea2e6-37e0-4421-b763-73bb5a55dd9f'
[36m[2021-05-21 19:43:09 DEBUG] [workspace:108][39m Saving workspace at ../../chaos/experiments/pod-experiments/terminate-pods/running-and-ready/.chaosiq
[36m[2021-05-21 19:43:09 DEBUG] [__init__:39][39m Initializing controls
[32m[2021-05-21 19:43:09 INFO] [run:342][39m Steady-state strategy: default
[32m[2021-05-21 19:43:09 INFO] [run:345][39m Rollbacks strategy: always
[36m[2021-05-21 19:43:09 DEBUG] [__init__:365][39m Applying before-control 'chaosiq-cloud' on 'experiment'
[36m[2021-05-21 19:43:09 DEBUG] [python:166][39m Control 'before_experiment_control' loaded from '/home/luisreciomelero/.local/lib/python3.8/site-packages/chaoscloud/controls.py'
[36m[2021-05-21 19:43:09 DEBUG] [execution:148][39m Cannot send event to ChaosIQ because execution identifier was not found in the experiment's extensions block.
[36m[2021-05-21 19:43:09 DEBUG] [run:466][39m Running steady-state hypothesis before the method
[32m[2021-05-21 19:43:09 INFO] [hypothesis:183][39m Steady state hypothesis: Pod exists
[36m[2021-05-21 19:43:09 DEBUG] [__init__:365][39m Applying before-control 'chaosiq-cloud' on 'hypothesis'
[36m[2021-05-21 19:43:09 DEBUG] [python:166][39m Control 'before_hypothesis_control' loaded from '/home/luisreciomelero/.local/lib/python3.8/site-packages/chaoscloud/controls.py'
[36m[2021-05-21 19:43:09 DEBUG] [execution:148][39m Cannot send event to ChaosIQ because execution identifier was not found in the experiment's extensions block.
[36m[2021-05-21 19:43:09 DEBUG] [__init__:365][39m Applying before-control 'chaosiq-cloud' on 'activity'
[36m[2021-05-21 19:43:09 DEBUG] [python:166][39m Control 'before_activity_control' loaded from '/home/luisreciomelero/.local/lib/python3.8/site-packages/chaoscloud/controls.py'
[36m[2021-05-21 19:43:09 DEBUG] [execution:148][39m Cannot send event to ChaosIQ because execution identifier was not found in the experiment's extensions block.
[32m[2021-05-21 19:43:09 INFO] [activity:161][39m Probe: pod-exists
[36m[2021-05-21 19:43:09 DEBUG] [python:34][39m Activity 'pod-exists' loaded from '/home/luisreciomelero/.local/lib/python3.8/site-packages/chaosk8s/pod/probes.py'
[36m[2021-05-21 19:43:09 DEBUG] [__init__:65][39m Using Kubernetes context: default
[36m[2021-05-21 19:43:09 DEBUG] [probes:202][39m Found 2 pods matching label 'app=mg-backend' in ns 'default'
[36m[2021-05-21 19:43:09 DEBUG] [activity:180][39m   => succeeded with '2'
[36m[2021-05-21 19:43:09 DEBUG] [__init__:365][39m Applying after-control 'chaosiq-cloud' on 'activity'
[36m[2021-05-21 19:43:09 DEBUG] [python:166][39m Control 'after_activity_control' loaded from '/home/luisreciomelero/.local/lib/python3.8/site-packages/chaoscloud/controls.py'
[36m[2021-05-21 19:43:09 DEBUG] [execution:148][39m Cannot send event to ChaosIQ because execution identifier was not found in the experiment's extensions block.
[36m[2021-05-21 19:43:09 DEBUG] [hypothesis:211][39m allowed tolerance is 2
[36m[2021-05-21 19:43:09 DEBUG] [__init__:365][39m Applying before-control 'chaosiq-cloud' on 'activity'
[36m[2021-05-21 19:43:09 DEBUG] [python:166][39m Control 'before_activity_control' loaded from '/home/luisreciomelero/.local/lib/python3.8/site-packages/chaoscloud/controls.py'
[36m[2021-05-21 19:43:09 DEBUG] [execution:148][39m Cannot send event to ChaosIQ because execution identifier was not found in the experiment's extensions block.
[32m[2021-05-21 19:43:09 INFO] [activity:161][39m Probe: pod-in-phase
[36m[2021-05-21 19:43:09 DEBUG] [python:34][39m Activity 'pod-in-phase' loaded from '/home/luisreciomelero/.local/lib/python3.8/site-packages/chaosk8s/pod/probes.py'
[36m[2021-05-21 19:43:09 DEBUG] [__init__:65][39m Using Kubernetes context: default
[36m[2021-05-21 19:43:09 DEBUG] [probes:97][39m Found 2 pods matching label 'app=mg-backend' in ns 'default'
[36m[2021-05-21 19:43:09 DEBUG] [activity:180][39m   => succeeded with 'True'
[36m[2021-05-21 19:43:09 DEBUG] [__init__:365][39m Applying after-control 'chaosiq-cloud' on 'activity'
[36m[2021-05-21 19:43:09 DEBUG] [python:166][39m Control 'after_activity_control' loaded from '/home/luisreciomelero/.local/lib/python3.8/site-packages/chaoscloud/controls.py'
[36m[2021-05-21 19:43:09 DEBUG] [execution:148][39m Cannot send event to ChaosIQ because execution identifier was not found in the experiment's extensions block.
[36m[2021-05-21 19:43:09 DEBUG] [hypothesis:211][39m allowed tolerance is True
[36m[2021-05-21 19:43:09 DEBUG] [__init__:365][39m Applying before-control 'chaosiq-cloud' on 'activity'
[36m[2021-05-21 19:43:09 DEBUG] [python:166][39m Control 'before_activity_control' loaded from '/home/luisreciomelero/.local/lib/python3.8/site-packages/chaoscloud/controls.py'
[36m[2021-05-21 19:43:09 DEBUG] [execution:148][39m Cannot send event to ChaosIQ because execution identifier was not found in the experiment's extensions block.
[32m[2021-05-21 19:43:09 INFO] [activity:161][39m Probe: pod-in-conditions
[36m[2021-05-21 19:43:09 DEBUG] [python:34][39m Activity 'pod-in-conditions' loaded from '/home/luisreciomelero/.local/lib/python3.8/site-packages/chaosk8s/pod/probes.py'
[36m[2021-05-21 19:43:09 DEBUG] [__init__:65][39m Using Kubernetes context: default
[36m[2021-05-21 19:43:09 DEBUG] [probes:130][39m Found 2 pods matching label 'app=mg-backend' in ns 'default'
[36m[2021-05-21 19:43:09 DEBUG] [activity:180][39m   => succeeded with 'True'
[36m[2021-05-21 19:43:09 DEBUG] [__init__:365][39m Applying after-control 'chaosiq-cloud' on 'activity'
[36m[2021-05-21 19:43:09 DEBUG] [python:166][39m Control 'after_activity_control' loaded from '/home/luisreciomelero/.local/lib/python3.8/site-packages/chaoscloud/controls.py'
[36m[2021-05-21 19:43:09 DEBUG] [execution:148][39m Cannot send event to ChaosIQ because execution identifier was not found in the experiment's extensions block.
[36m[2021-05-21 19:43:09 DEBUG] [hypothesis:211][39m allowed tolerance is True
[36m[2021-05-21 19:43:09 DEBUG] [__init__:365][39m Applying before-control 'chaosiq-cloud' on 'activity'
[36m[2021-05-21 19:43:09 DEBUG] [python:166][39m Control 'before_activity_control' loaded from '/home/luisreciomelero/.local/lib/python3.8/site-packages/chaoscloud/controls.py'
[36m[2021-05-21 19:43:09 DEBUG] [execution:148][39m Cannot send event to ChaosIQ because execution identifier was not found in the experiment's extensions block.
[32m[2021-05-21 19:43:09 INFO] [activity:161][39m Probe: app-responds-to-requests
[36m[2021-05-21 19:43:09 DEBUG] [activity:180][39m   => succeeded with '{'status': 200, 'headers': {'content-type': 'application/json; charset=UTF-8', 'content-length': '1284', 'x-envoy-upstream-service-time': '235', 'date': 'Fri, 21 May 2021 17:43:09 GMT', 'server': 'istio-envoy'}, 'body': '\n{\n    "status": "UP",\n    "checks": [\n        {\n            "name": "Liveness check",\n            "status": "UP"\n        },\n        {\n            "name": "SmallRye Reactive Messaging - liveness check",\n            "status": "UP",\n            "data": {\n                "usuarios-delete": "[OK]",\n                "usuarios-sendemail": "[OK]",\n                "usuarios-sendnotification": "[OK]",\n                "usuarios-create": "[OK]",\n                "handlednotification-usuarios": "[OK]",\n                "usuarios-update": "[OK]",\n                "usuarios-sendsms": "[OK]"\n            }\n        },\n        {\n            "name": "Database connections health check",\n            "status": "UP"\n        },\n        {\n            "name": "Readiness check",\n            "status": "UP"\n        },\n        {\n            "name": "SmallRye Reactive Messaging - readiness check",\n            "status": "UP",\n            "data": {\n                "usuarios-delete": "[OK]",\n                "usuarios-sendemail": "[OK]",\n                "usuarios-sendnotification": "[OK]",\n                "usuarios-create": "[OK]",\n                "handlednotification-usuarios": "[OK]",\n                "usuarios-update": "[OK]",\n                "usuarios-sendsms": "[OK]"\n            }\n        }\n    ]\n}'}'
[36m[2021-05-21 19:43:09 DEBUG] [__init__:365][39m Applying after-control 'chaosiq-cloud' on 'activity'
[36m[2021-05-21 19:43:09 DEBUG] [python:166][39m Control 'after_activity_control' loaded from '/home/luisreciomelero/.local/lib/python3.8/site-packages/chaoscloud/controls.py'
[36m[2021-05-21 19:43:09 DEBUG] [execution:148][39m Cannot send event to ChaosIQ because execution identifier was not found in the experiment's extensions block.
[36m[2021-05-21 19:43:09 DEBUG] [hypothesis:211][39m allowed tolerance is 200
[32m[2021-05-21 19:43:09 INFO] [hypothesis:221][39m Steady state hypothesis is met!
[36m[2021-05-21 19:43:09 DEBUG] [__init__:365][39m Applying after-control 'chaosiq-cloud' on 'hypothesis'
[36m[2021-05-21 19:43:09 DEBUG] [python:166][39m Control 'after_hypothesis_control' loaded from '/home/luisreciomelero/.local/lib/python3.8/site-packages/chaoscloud/controls.py'
[36m[2021-05-21 19:43:09 DEBUG] [execution:148][39m Cannot send event to ChaosIQ because execution identifier was not found in the experiment's extensions block.
[32m[2021-05-21 19:43:09 INFO] [run:553][39m Playing your experiment's method now...
[36m[2021-05-21 19:43:09 DEBUG] [__init__:365][39m Applying before-control 'chaosiq-cloud' on 'method'
[36m[2021-05-21 19:43:09 DEBUG] [python:166][39m Control 'before_method_control' loaded from '/home/luisreciomelero/.local/lib/python3.8/site-packages/chaoscloud/controls.py'
[36m[2021-05-21 19:43:09 DEBUG] [execution:148][39m Cannot send event to ChaosIQ because execution identifier was not found in the experiment's extensions block.
[36m[2021-05-21 19:43:09 DEBUG] [__init__:365][39m Applying before-control 'chaosiq-cloud' on 'activity'
[36m[2021-05-21 19:43:09 DEBUG] [python:166][39m Control 'before_activity_control' loaded from '/home/luisreciomelero/.local/lib/python3.8/site-packages/chaoscloud/controls.py'
[36m[2021-05-21 19:43:09 DEBUG] [execution:148][39m Cannot send event to ChaosIQ because execution identifier was not found in the experiment's extensions block.
[32m[2021-05-21 19:43:09 INFO] [activity:161][39m Action: terminate-pod
[36m[2021-05-21 19:43:09 DEBUG] [python:34][39m Activity 'terminate-pod' loaded from '/home/luisreciomelero/.local/lib/python3.8/site-packages/chaosk8s/pod/actions.py'
[36m[2021-05-21 19:43:09 DEBUG] [__init__:65][39m Using Kubernetes context: default
[36m[2021-05-21 19:43:09 DEBUG] [actions:193][39m Found 2 pods labelled 'app=mg-backend' in ns default
[36m[2021-05-21 19:43:10 DEBUG] [activity:182][39m   => succeeded without any result value
[32m[2021-05-21 19:43:10 INFO] [activity:198][39m Pausing after activity for 20s...
[36m[2021-05-21 19:43:30 DEBUG] [__init__:365][39m Applying after-control 'chaosiq-cloud' on 'activity'
[36m[2021-05-21 19:43:30 DEBUG] [python:166][39m Control 'after_activity_control' loaded from '/home/luisreciomelero/.local/lib/python3.8/site-packages/chaoscloud/controls.py'
[36m[2021-05-21 19:43:30 DEBUG] [execution:148][39m Cannot send event to ChaosIQ because execution identifier was not found in the experiment's extensions block.
[36m[2021-05-21 19:43:30 DEBUG] [__init__:365][39m Applying after-control 'chaosiq-cloud' on 'method'
[36m[2021-05-21 19:43:30 DEBUG] [python:166][39m Control 'after_method_control' loaded from '/home/luisreciomelero/.local/lib/python3.8/site-packages/chaoscloud/controls.py'
[36m[2021-05-21 19:43:30 DEBUG] [execution:148][39m Cannot send event to ChaosIQ because execution identifier was not found in the experiment's extensions block.
[36m[2021-05-21 19:43:30 DEBUG] [run:496][39m Running steady-state hypothesis after the method
[32m[2021-05-21 19:43:30 INFO] [hypothesis:183][39m Steady state hypothesis: Pod exists
[36m[2021-05-21 19:43:30 DEBUG] [__init__:365][39m Applying before-control 'chaosiq-cloud' on 'hypothesis'
[36m[2021-05-21 19:43:30 DEBUG] [python:166][39m Control 'before_hypothesis_control' loaded from '/home/luisreciomelero/.local/lib/python3.8/site-packages/chaoscloud/controls.py'
[36m[2021-05-21 19:43:30 DEBUG] [execution:148][39m Cannot send event to ChaosIQ because execution identifier was not found in the experiment's extensions block.
[36m[2021-05-21 19:43:30 DEBUG] [__init__:365][39m Applying before-control 'chaosiq-cloud' on 'activity'
[36m[2021-05-21 19:43:30 DEBUG] [python:166][39m Control 'before_activity_control' loaded from '/home/luisreciomelero/.local/lib/python3.8/site-packages/chaoscloud/controls.py'
[36m[2021-05-21 19:43:30 DEBUG] [execution:148][39m Cannot send event to ChaosIQ because execution identifier was not found in the experiment's extensions block.
[32m[2021-05-21 19:43:30 INFO] [activity:161][39m Probe: pod-exists
[36m[2021-05-21 19:43:30 DEBUG] [python:34][39m Activity 'pod-exists' loaded from '/home/luisreciomelero/.local/lib/python3.8/site-packages/chaosk8s/pod/probes.py'
[36m[2021-05-21 19:43:30 DEBUG] [__init__:65][39m Using Kubernetes context: default
[36m[2021-05-21 19:43:30 DEBUG] [probes:202][39m Found 3 pods matching label 'app=mg-backend' in ns 'default'
[36m[2021-05-21 19:43:30 DEBUG] [activity:180][39m   => succeeded with '3'
[36m[2021-05-21 19:43:30 DEBUG] [__init__:365][39m Applying after-control 'chaosiq-cloud' on 'activity'
[36m[2021-05-21 19:43:30 DEBUG] [python:166][39m Control 'after_activity_control' loaded from '/home/luisreciomelero/.local/lib/python3.8/site-packages/chaoscloud/controls.py'
[36m[2021-05-21 19:43:30 DEBUG] [execution:148][39m Cannot send event to ChaosIQ because execution identifier was not found in the experiment's extensions block.
[36m[2021-05-21 19:43:30 DEBUG] [hypothesis:211][39m allowed tolerance is 2
[36m[2021-05-21 19:43:30 DEBUG] [__init__:365][39m Applying after-control 'chaosiq-cloud' on 'hypothesis'
[36m[2021-05-21 19:43:30 DEBUG] [python:166][39m Control 'after_hypothesis_control' loaded from '/home/luisreciomelero/.local/lib/python3.8/site-packages/chaoscloud/controls.py'
[36m[2021-05-21 19:43:30 DEBUG] [execution:148][39m Cannot send event to ChaosIQ because execution identifier was not found in the experiment's extensions block.
[31m[2021-05-21 19:43:30 CRITICAL] [run:507][39m Steady state probe 'pod-exists' is not in the given tolerance so failing this experiment
[33m[2021-05-21 19:43:30 WARNING] [run:580][39m Rollbacks were explicitly requested to be played
[32m[2021-05-21 19:43:30 INFO] [run:809][39m Let's rollback...
[36m[2021-05-21 19:43:30 DEBUG] [__init__:365][39m Applying before-control 'chaosiq-cloud' on 'rollback'
[36m[2021-05-21 19:43:30 DEBUG] [python:166][39m Control 'before_rollback_control' loaded from '/home/luisreciomelero/.local/lib/python3.8/site-packages/chaoscloud/controls.py'
[36m[2021-05-21 19:43:30 DEBUG] [execution:148][39m Cannot send event to ChaosIQ because execution identifier was not found in the experiment's extensions block.
[32m[2021-05-21 19:43:30 INFO] [rollback:25][39m No declared rollbacks, let's move on.
[36m[2021-05-21 19:43:30 DEBUG] [__init__:365][39m Applying after-control 'chaosiq-cloud' on 'rollback'
[36m[2021-05-21 19:43:30 DEBUG] [python:166][39m Control 'after_rollback_control' loaded from '/home/luisreciomelero/.local/lib/python3.8/site-packages/chaoscloud/controls.py'
[36m[2021-05-21 19:43:30 DEBUG] [execution:148][39m Cannot send event to ChaosIQ because execution identifier was not found in the experiment's extensions block.
[32m[2021-05-21 19:43:30 INFO] [run:421][39m Experiment ended with status: deviated
[32m[2021-05-21 19:43:30 INFO] [run:423][39m The steady-state has deviated, a weakness may have been discovered
[36m[2021-05-21 19:43:30 DEBUG] [__init__:365][39m Applying after-control 'chaosiq-cloud' on 'experiment'
[36m[2021-05-21 19:43:30 DEBUG] [python:166][39m Control 'after_experiment_control' loaded from '/home/luisreciomelero/.local/lib/python3.8/site-packages/chaoscloud/controls.py'
[36m[2021-05-21 19:43:30 DEBUG] [execution:148][39m Cannot send event to ChaosIQ because execution identifier was not found in the experiment's extensions block.
[36m[2021-05-21 19:43:30 DEBUG] [execution:82][39m Cannot publish execution to ChaosIQ because execution identifier was not found in the experiment's extensions block.
[36m[2021-05-21 19:43:30 DEBUG] [__init__:72][39m Cleaning up controls
[36m[2021-05-21 19:43:30 DEBUG] [__init__:188][39m Cleaning up global control 'chaosiq-cloud'
[36m[2021-05-21 19:43:30 DEBUG] [python:159][39m Control module '/home/luisreciomelero/.local/lib/python3.8/site-packages/chaoscloud/controls.py' does not declare 'cleanup_control'
[36m[2021-05-21 19:43:30 DEBUG] [caching:42][39m Clearing activities cache
[36m[2021-05-21 17:46:14 DEBUG][39m ###############################################################################
[36m[2021-05-21 17:46:14 DEBUG][39m Running command 'report'
[36m[2021-05-21 17:46:14 DEBUG][39m Using settings file '/.chaostoolkit/settings.yaml'
[33m[2021-05-21 17:46:16 WARNING][39m 
    There is a new version (1.9.0) of the chaostoolkit available.
    You may upgrade by typing:
    
    $ pip install -U chaostoolkit
    
    Please review changes at https://github.com/chaostoolkit/chaostoolkit/blob/master/CHANGELOG.md
    
[36m[2021-05-21 17:46:16 DEBUG][39m Building activity cache...
[36m[2021-05-21 17:46:16 DEBUG][39m Cached 5 activities
